Workbook

Sheet README
A1: One Rosslyn - reference model
A3: Status | B3: PROJECTION. The project is entitled and unbuilt.
A4: Purpose | B4: Independent implementation. The CFDL model reconciles to this.
A6: Fact | B6: Program and obligations: Arlington County Board Report, SP #419 /
B7: SPLA24-00040, approved 2025-07-19.
B8: Land: $52,000,000, deed 20230100013266, recorded 2023-11-14.
B9: Operating guidelines: Arlington 2026 Guidebook, MARKET Apartment
B10: Guidelines, High-Rise 9+ (PCC 313), 2010+, Metro.
B11: Exit comparables: four recorded Arlington trades, 2022-2026.
A13: Derived | B13: Rent, by the County's own method: a comparable's assessed value
B14: times the guideline loaded cap gives the assessor's NOI; add back
B15: guideline expenses and gross up for vacancy.
A17: Projection | B17: Construction cost and duration, debt pricing, lease-up pace,
B18: rent and expense growth, condominium pricing, and the JV tiers.
A20: Scenario A | B20: Merchant build. Sell in lease-up ~10 months after delivery.
B21: This is what Penzance and Baupost actually did at The Highlands:
B22: both towers sold 2022-05-17 at 83% and 60% occupancy.
A23: Scenario B | B23: Build to core. Stabilize, refinance into permanent debt,
B24: hold five years, exit on escalated NOI.
A26: NOT a claim | B26: Nothing here states what Penzance will earn.

Sheet Assumptions
A1: ASSUMPTIONS
A3: SOURCE
A4: Model start | B4: 2023-11 | D4: Land acquisition, recorded
A5: Periods | B5: 170 | C5: months | D5: to 2037-12
A7: PROGRAM - FACT (Board Report SP #419)
A8: Residential GFA | B8: 957306 | C8: sf
A9: Retail GFA | B9: 14584 | C9: sf
A10: Total GFA | B10: 971890 | C10: sf
A11: Dwelling units | B11: 845 | C11: units | D11: 845 = 73 + 311 + 461
A12: NE tower (condominium) | B12: 73 | C12: units | D12: for sale
A13: NW tower | B13: 311 | C13: units | D13: rental
A14: S tower | B14: 461 | C14: units | D14: rental
A15: Rental units | B15: 772 | C15: units
A16: Parking spaces | B16: 429 | C16: spaces | D16: 0.51 per unit
A18: LAND - FACT
A19: Purchase price | B19: 52000000 | C19: $ | D19: deed 20230100013266
A20: 2026 assessed, 3 parcels | B20: 66786000 | C20: $ | D20: purchase is 77.9% of assessed
A21: County guideline land value | B21: 78000 | C21: $/rental unit | D21: Metro high-rise; 772 units = $60.2M
A23: PUBLIC OBLIGATIONS - FACT, and the timing is fact too
A24: AHIF base density | B24: 3672828 | C24: $ | D24: at construction start
A25: AHIF - NE tower | B25: 651858 | C25: $ | D25: at first partial CO
A26: AHIF - NW tower | B26: 2777096 | C26: $ | D26: at first partial CO
A27: AHIF - S tower | B27: 4116531 | C27: $ | D27: at first partial CO
A28: Public space (RMSA) | B28: 2000000 | C28: $
A29: Transportation (RMSA) | B29: 3000000 | C29: $
A31: CONSTRUCTION - anchored to The Highlands actual spend
A32: Buildings, Highlands | B32: 255 | C32: $/sf GFA | D32: $301,693,050 / 1,183,110 sf
A33: Parking, Highlands | B33: 32000 | C33: $/space | D33: $33,184,000 / 1,037 spaces
A34: Escalation, realized | B34: 1.534 | C34: x | D34: BLS WPUIP2312001, 2019-11 to 2026-07
A35: Escalation, forward | B35: 0.0343 | C35: /yr | D35: 36-month trailing on same index
A36: Escalation years forward | B36: 2.17 | C36: yrs | D36: 2026-07 to 2028-09 midpoint
A37: Soft cost ratio | B37: 0.180893 | C37: of hard | D37: Highlands
A38: Contingency ratio | B38: 0.053203 | C38: of hard | D38: Highlands
A39: Developer fee ratio | B39: 0.053736 | C39: of hard | D39: Highlands
A40: Construction start | B40: 37 | C40: month # | D40: 2026-12, reported
A41: Construction months | B41: 42 | C41: months | D41: PROJECTION
A43: OPERATIONS - FACT (Arlington 2026 Guidebook, MARKET, PCC 313, 2010+)
A44: Loaded cap rate, Metro | B44: 0.0545 | D44: 5.45%
A45: Expenses per unit | B45: 9466 | C45: $/unit/yr | D45: 2026 dollars
A46: Vacancy and collection | B46: 0.05 | D46: includes concessions
...

Sheet CashFlow
A1: MONTHLY CASH FLOW - construction and operations, before exit and scenario financing
A2: Development cost is a parabolic draw over the construction window. Equity funds to its commitment first; the facility draws the residual and capitalizes interest.
A3: Rent, parking and expenses escalate at the growth rate from the 2026 guideline base (month 32 = 2026-07). Freezing them at 2026 for a 2030 delivery would understate the deal.
A7: Month # | B7: Date | C7: Dev cost | D7: Cum dev | E7: Equity draw | F7: Cum equity | G7: Loan draw | H7: Interest cap | I7: Loan bal EOP | J7: Units occ | K7: Rent | L7: Parking | M7: Opex | N7: NOI | O7: Condo net | P7: Unlevered CF
A8: 0 | B8: 2023-11 | C8: 52000000 | D8: =C8 | E8: 52000000 | F8: =E8 | G8: 0 | H8: 0 | I8: =G8+H8 | J8: 0 | K8: =J8*Assumptions!$B$47*(1+Assumptions!$B$49)^((A8-32)/12) | L8: =J8*Assumptions!$B$48*0.5*(1+Assumptions!$B$49)^((A8-32)/12) | M8: =J8*Assumptions!$B$45/12*(1+Assumptions!$B$49)^((A8-32)/12) | N8: =K8+L8-M8 | O8: 0 | P8: =N8+O8-C8
A9: 1 | B9: 2023-12 | C9: 0 | D9: =D8+C9 | E9: 0 | F9: =F8+E9 | G9: 0 | H9: =I8*Assumptions!$B$66/12 | I9: =I8+G9+H9 | J9: 0 | K9: =J9*Assumptions!$B$47*(1+Assumptions!$B$49)^((A9-32)/12) | L9: =J9*Assumptions!$B$48*0.5*(1+Assumptions!$B$49)^((A9-32)/12) | M9: =J9*Assumptions!$B$45/12*(1+Assumptions!$B$49)^((A9-32)/12) | N9: =K9+L9-M9 | O9: 0 | P9: =N9+O9-C9
A10: 2 | B10: 2024-01 | C10: 0 | D10: =D9+C10 | E10: 0 | F10: =F9+E10 | G10: 0 | H10: =I9*Assumptions!$B$66/12 | I10: =I9+G10+H10 | J10: 0 | K10: =J10*Assumptions!$B$47*(1+Assumptions!$B$49)^((A10-32)/12) | L10: =J10*Assumptions!$B$48*0.5*(1+Assumptions!$B$49)^((A10-32)/12) | M10: =J10*Assumptions!$B$45/12*(1+Assumptions!$B$49)^((A10-32)/12) | N10: =K10+L10-M10 | O10: 0 | P10: =N10+O10-C10
A11: 3 | B11: 2024-02 | C11: 0 | D11: =D10+C11 | E11: 0 | F11: =F10+E11 | G11: 0 | H11: =I10*Assumptions!$B$66/12 | I11: =I10+G11+H11 | J11: 0 | K11: =J11*Assumptions!$B$47*(1+Assumptions!$B$49)^((A11-32)/12) | L11: =J11*Assumptions!$B$48*0.5*(1+Assumptions!$B$49)^((A11-32)/12) | M11: =J11*Assumptions!$B$45/12*(1+Assumptions!$B$49)^((A11-32)/12) | N11: =K11+L11-M11 | O11: 0 | P11: =N11+O11-C11
A12: 4 | B12: 2024-03 | C12: 0 | D12: =D11+C12 | E12: 0 | F12: =F11+E12 | G12: 0 | H12: =I11*Assumptions!$B$66/12 | I12: =I11+G12+H12 | J12: 0 | K12: =J12*Assumptions!$B$47*(1+Assumptions!$B$49)^((A12-32)/12) | L12: =J12*Assumptions!$B$48*0.5*(1+Assumptions!$B$49)^((A12-32)/12) | M12: =J12*Assumptions!$B$45/12*(1+Assumptions!$B$49)^((A12-32)/12) | N12: =K12+L12-M12 | O12: 0 | P12: =N12+O12-C12
A13: 5 | B13: 2024-04 | C13: 0 | D13: =D12+C13 | E13: 0 | F13: =F12+E13 | G13: 0 | H13: =I12*Assumptions!$B$66/12 | I13: =I12+G13+H13 | J13: 0 | K13: =J13*Assumptions!$B$47*(1+Assumptions!$B$49)^((A13-32)/12) | L13: =J13*Assumptions!$B$48*0.5*(1+Assumptions!$B$49)^((A13-32)/12) | M13: =J13*Assumptions!$B$45/12*(1+Assumptions!$B$49)^((A13-32)/12) | N13: =K13+L13-M13 | O13: 0 | P13: =N13+O13-C13
A14: 6 | B14: 2024-05 | C14: 0 | D14: =D13+C14 | E14: 0 | F14: =F13+E14 | G14: 0 | H14: =I13*Assumptions!$B$66/12 | I14: =I13+G14+H14 | J14: 0 | K14: =J14*Assumptions!$B$47*(1+Assumptions!$B$49)^((A14-32)/12) | L14: =J14*Assumptions!$B$48*0.5*(1+Assumptions!$B$49)^((A14-32)/12) | M14: =J14*Assumptions!$B$45/12*(1+Assumptions!$B$49)^((A14-32)/12) | N14: =K14+L14-M14 | O14: 0 | P14: =N14+O14-C14
A15: 7 | B15: 2024-06 | C15: 0 | D15: =D14+C15 | E15: 0 | F15: =F14+E15 | G15: 0 | H15: =I14*Assumptions!$B$66/12 | I15: =I14+G15+H15 | J15: 0 | K15: =J15*Assumptions!$B$47*(1+Assumptions!$B$49)^((A15-32)/12) | L15: =J15*Assumptions!$B$48*0.5*(1+Assumptions!$B$49)^((A15-32)/12) | M15: =J15*Assumptions!$B$45/12*(1+Assumptions!$B$49)^((A15-32)/12) | N15: =K15+L15-M15 | O15: 0 | P15: =N15+O15-C15
A16: 8 | B16: 2024-07 | C16: 0 | D16: =D15+C16 | E16: 0 | F16: =F15+E16 | G16: 0 | H16: =I15*Assumptions!$B$66/12 | I16: =I15+G16+H16 | J16: 0 | K16: =J16*Assumptions!$B$47*(1+Assumptions!$B$49)^((A16-32)/12) | L16: =J16*Assumptions!$B$48*0.5*(1+Assumptions!$B$49)^((A16-32)/12) | M16: =J16*Assumptions!$B$45/12*(1+Assumptions!$B$49)^((A16-32)/12) | N16: =K16+L16-M16 | O16: 0 | P16: =N16+O16-C16
A17: 9 | B17: 2024-08 | C17: 0 | D17: =D16+C17 | E17: 0 | F17: =F16+E17 | G17: 0 | H17: =I16*Assumptions!$B$66/12 | I17: =I16+G17+H17 | J17: 0 | K17: =J17*Assumptions!$B$47*(1+Assumptions!$B$49)^((A17-32)/12) | L17: =J17*Assumptions!$B$48*0.5*(1+Assumptions!$B$49)^((A17-32)/12) | M17: =J17*Assumptions!$B$45/12*(1+Assumptions!$B$49)^((A17-32)/12) | N17: =K17+L17-M17 | O17: 0 | P17: =N17+O17-C17
A18: 10 | B18: 2024-09 | C18: 0 | D18: =D17+C18 | E18: 0 | F18: =F17+E18 | G18: 0 | H18: =I17*Assumptions!$B$66/12 | I18: =I17+G18+H18 | J18: 0 | K18: =J18*Assumptions!$B$47*(1+Assumptions!$B$49)^((A18-32)/12) | L18: =J18*Assumptions!$B$48*0.5*(1+Assumptions!$B$49)^((A18-32)/12) | M18: =J18*Assumptions!$B$45/12*(1+Assumptions!$B$49)^((A18-32)/12) | N18: =K18+L18-M18 | O18: 0 | P18: =N18+O18-C18
A19: 11 | B19: 2024-10 | C19: 0 | D19: =D18+C19 | E19: 0 | F19: =F18+E19 | G19: 0 | H19: =I18*Assumptions!$B$66/12 | I19: =I18+G19+H19 | J19: 0 | K19: =J19*Assumptions!$B$47*(1+Assumptions!$B$49)^((A19-32)/12) | L19: =J19*Assumptions!$B$48*0.5*(1+Assumptions!$B$49)^((A19-32)/12) | M19: =J19*Assumptions!$B$45/12*(1+Assumptions!$B$49)^((A19-32)/12) | N19: =K19+L19-M19 | O19: 0 | P19: =N19+O19-C19
A20: 12 | B20: 2024-11 | C20: 0 | D20: =D19+C20 | E20: 0 | F20: =F19+E20 | G20: 0 | H20: =I19*Assumptions!$B$66/12 | I20: =I19+G20+H20 | J20: 0 | K20: =J20*Assumptions!$B$47*(1+Assumptions!$B$49)^((A20-32)/12) | L20: =J20*Assumptions!$B$48*0.5*(1+Assumptions!$B$49)^((A20-32)/12) | M20: =J20*Assumptions!$B$45/12*(1+Assumptions!$B$49)^((A20-32)/12) | N20: =K20+L20-M20 | O20: 0 | P20: =N20+O20-C20
... A171: 163 | B171: 2037-06 | C171: 0 | D171: =D170+C171 | E171: 0 | F171: =F170+E171 | G171: 0 | H171: =I170*Assumptions!$B$66/12 | I171: =I170+G171+H171 | J171: 733.4 | K171: =J171*Assumptions!$B$47*(1+Assumptions!$B$49)^((A171-32)/12) | L171: =J171*Assumptions!$B$48*0.5*(1+Assumptions!$B$49)^((A171-32)/12) | M171: =J171*Assumptions!$B$45/12*(1+Assumptions!$B$49)^((A171-32)/12) | N171: =K171+L171-M171 | O171: 0 | P171: =N171+O171-C171
A172: TOTAL | C172: =SUM(C8:C171) | E172: =SUM(E8:E171) | G172: =SUM(G8:G171) | H172: =SUM(H8:H171) | K172: =SUM(K8:K171) | L172: =SUM(L8:L171) | M172: =SUM(M8:M171) | N172: =SUM(N8:N171) | O172: =SUM(O8:O171) | P172: =SUM(P8:P171)

Sheet ScenarioA
A1: SCENARIO A - merchant build, sell in lease-up (the Highlands precedent)
A2: Priced on STABILIZED NOI over the County guideline cap, market factor 1.00. A lease-up sale is priced on what the asset will produce, not on in-place NOI.
A6: Month # | B6: Date | C6: NOI | D6: Dev cost | E6: Loan draw | F6: Interest cap | G6: Loan bal EOP | H6: Proceeds | I6: Loan repay | J6: Equity CF
A7: 0 | B7: 2023-11 | C7: 0 | D7: 52000000 | E7: 0 | F7: 0 | G7: 0 | H7: 0 | I7: 0 | J7: -52000000
A8: 1 | B8: 2023-12 | C8: 0 | D8: 0 | E8: 0 | F8: 0 | G8: 0 | H8: 0 | I8: 0 | J8: 0
A9: 2 | B9: 2024-01 | C9: 0 | D9: 0 | E9: 0 | F9: 0 | G9: 0 | H9: 0 | I9: 0 | J9: 0
A10: 3 | B10: 2024-02 | C10: 0 | D10: 0 | E10: 0 | F10: 0 | G10: 0 | H10: 0 | I10: 0 | J10: 0
A11: 4 | B11: 2024-03 | C11: 0 | D11: 0 | E11: 0 | F11: 0 | G11: 0 | H11: 0 | I11: 0 | J11: 0
A12: 5 | B12: 2024-04 | C12: 0 | D12: 0 | E12: 0 | F12: 0 | G12: 0 | H12: 0 | I12: 0 | J12: 0
A13: 6 | B13: 2024-05 | C13: 0 | D13: 0 | E13: 0 | F13: 0 | G13: 0 | H13: 0 | I13: 0 | J13: 0
A14: 7 | B14: 2024-06 | C14: 0 | D14: 0 | E14: 0 | F14: 0 | G14: 0 | H14: 0 | I14: 0 | J14: 0
A15: 8 | B15: 2024-07 | C15: 0 | D15: 0 | E15: 0 | F15: 0 | G15: 0 | H15: 0 | I15: 0 | J15: 0
A16: 9 | B16: 2024-08 | C16: 0 | D16: 0 | E16: 0 | F16: 0 | G16: 0 | H16: 0 | I16: 0 | J16: 0
A17: 10 | B17: 2024-09 | C17: 0 | D17: 0 | E17: 0 | F17: 0 | G17: 0 | H17: 0 | I17: 0 | J17: 0
A18: 11 | B18: 2024-10 | C18: 0 | D18: 0 | E18: 0 | F18: 0 | G18: 0 | H18: 0 | I18: 0 | J18: 0
... A109: 102 | B109: 2032-05 | C109: 0 | D109: 0 | E109: 0 | F109: 0 | G109: 0 | H109: 5387833.3 | I109: 0 | J109: 5387833.3
A110: TOTAL | C110: =SUM(C7:C109) | D110: =SUM(D7:D109) | E110: =SUM(E7:E109) | F110: =SUM(F7:F109) | G110: =SUM(G7:G109) | H110: =SUM(H7:H109) | I110: =SUM(I7:I109) | J110: =SUM(J7:J109)

Sheet ScenarioB
A1: SCENARIO B - build to core, refinance at stabilization, hold five years
A2: Priced on STABILIZED NOI over the County guideline cap, market factor 1.00. A lease-up sale is priced on what the asset will produce, not on in-place NOI.
A6: Month # | B6: Date | C6: NOI | D6: Dev cost | E6: Loan draw | F6: Interest cap | G6: Constr bal | H6: Condo/refi in | I6: Refinance | J6: Perm debt svc | K6: Sale | L6: Perm payoff | M6: Loan repay | N6: Equity CF
A7: 0 | B7: 2023-11 | C7: 0 | D7: 52000000 | E7: 0 | F7: 0 | G7: 0 | H7: 0 | I7: 0 | J7: 0 | K7: 0 | L7: 0 | M7: 0 | N7: -52000000
A8: 1 | B8: 2023-12 | C8: 0 | D8: 0 | E8: 0 | F8: 0 | G8: 0 | H8: 0 | I8: 0 | J8: 0 | K8: 0 | L8: 0 | M8: 0 | N8: 0
A9: 2 | B9: 2024-01 | C9: 0 | D9: 0 | E9: 0 | F9: 0 | G9: 0 | H9: 0 | I9: 0 | J9: 0 | K9: 0 | L9: 0 | M9: 0 | N9: 0
A10: 3 | B10: 2024-02 | C10: 0 | D10: 0 | E10: 0 | F10: 0 | G10: 0 | H10: 0 | I10: 0 | J10: 0 | K10: 0 | L10: 0 | M10: 0 | N10: 0
A11: 4 | B11: 2024-03 | C11: 0 | D11: 0 | E11: 0 | F11: 0 | G11: 0 | H11: 0 | I11: 0 | J11: 0 | K11: 0 | L11: 0 | M11: 0 | N11: 0
A12: 5 | B12: 2024-04 | C12: 0 | D12: 0 | E12: 0 | F12: 0 | G12: 0 | H12: 0 | I12: 0 | J12: 0 | K12: 0 | L12: 0 | M12: 0 | N12: 0
A13: 6 | B13: 2024-05 | C13: 0 | D13: 0 | E13: 0 | F13: 0 | G13: 0 | H13: 0 | I13: 0 | J13: 0 | K13: 0 | L13: 0 | M13: 0 | N13: 0
A14: 7 | B14: 2024-06 | C14: 0 | D14: 0 | E14: 0 | F14: 0 | G14: 0 | H14: 0 | I14: 0 | J14: 0 | K14: 0 | L14: 0 | M14: 0 | N14: 0
A15: 8 | B15: 2024-07 | C15: 0 | D15: 0 | E15: 0 | F15: 0 | G15: 0 | H15: 0 | I15: 0 | J15: 0 | K15: 0 | L15: 0 | M15: 0 | N15: 0
A16: 9 | B16: 2024-08 | C16: 0 | D16: 0 | E16: 0 | F16: 0 | G16: 0 | H16: 0 | I16: 0 | J16: 0 | K16: 0 | L16: 0 | M16: 0 | N16: 0
A17: 10 | B17: 2024-09 | C17: 0 | D17: 0 | E17: 0 | F17: 0 | G17: 0 | H17: 0 | I17: 0 | J17: 0 | K17: 0 | L17: 0 | M17: 0 | N17: 0
A18: 11 | B18: 2024-10 | C18: 0 | D18: 0 | E18: 0 | F18: 0 | G18: 0 | H18: 0 | I18: 0 | J18: 0 | K18: 0 | L18: 0 | M18: 0 | N18: 0
... A170: 163 | B170: 2037-06 | C170: 3088902.4 | D170: 0 | E170: 0 | F170: 0 | G170: 0 | H170: 0 | I170: 0 | J170: 2183248 | K170: 6.9112741e+08 | L170: 3.2484643e+08 | M170: 0 | N170: 3.6718664e+08
A171: TOTAL | C171: =SUM(C7:C170) | D171: =SUM(D7:D170) | E171: =SUM(E7:E170) | F171: =SUM(F7:F170) | G171: =SUM(G7:G170) | H171: =SUM(H7:H170) | I171: =SUM(I7:I170) | J171: =SUM(J7:J170) | ... N171: =SUM(N7:N170)

Sheet Returns
A1: RETURNS - two exit strategies over one set of facts
A2: Base case is the County guideline basis (market factor 1.00).
B4: Scenario A | C4: Scenario B
A5: Strategy | B5: merchant build | C5: build to core
A6: Exit | B6: 2031-10 | C6: 2037-06
A7: Months held from land | B7: 95 | C7: 163
A9: Construction cost | B9: 5.5595389e+08 | C9: 5.5595389e+08
A10: Equity commitment | B10: 2.4966888e+08 | C10: 2.4966888e+08
A11: Capitalized interest | B11: 58451635 | C11: 70146419
A12: Permanent loan | B12: 0 | C12: 3.4721783e+08
A13: Permanent debt service, monthly | B13: 0 | C13: 2183248
A15: Exit value | B15: 5.674043e+08 | C15: 6.9112741e+08
A16: Exit per unit | B16: 734979.66 | C16: 895242.77
A18: Equity in | B18: 3.0324665e+08 | C18: 3.0324665e+08
A19: Equity out | B19: 3.3183826e+08 | C19: 5.2704578e+08
A20: Net | B20: 28591606 | C20: 2.2379913e+08
A21: Multiple | B21: 1.094285 | C21: 1.73801
A22: IRR | B22: 0.020841 | C22: 0.066484
