Workbook

Sheet README
A1: THE HIGHLANDS — REFERENCE MODEL
A3: What this is | B3: The reference (oracle) model for the Penzance / The Highlands private benchmark. Deliberately conventional — the way a development shop would build it in Excel. The CFDL model must reproduce every number on the Returns sheet from the same inputs.
A4: Where inputs live | B4: inputs/highlands.toml is the single source of truth. This workbook was generated from it by model/build_reference_model.py. Change the TOML and rebuild; do not fork numbers here.
A5: Colour legend | B5: BLUE on YELLOW = editable assumption. GREEN = fact from SP #445, or a cross-sheet link. BLACK = formula. GREY fill = subtotal or headline.
A6: What is fact | B6: Program, unit counts, unit mix by tower, GFA, parking, FAR, heights, entitlement chronology, ground lease and development agreement dates, the cash public obligations with their triggers, the in-kind obligations (Fire Station 10, Rosslyn Highlands Park, N. Pierce Street), and both exit DATES.
A7: What is assumed | B7: Every dollar of cost, all debt pricing, all rents, all operating expense, lease-up and sellout pace, both exit PRICES, and the entire JV waterfall. Cortland never disclosed terms; the Baupost JV is private. No Penzance data was used — none is available.
A8: Structural features | B8: Three assets, ONE construction loan. The East Building holds BOTH the for-sale product (Pierce, North Tower) and rental (Evo, South Tower) over a shared podium, so their costs are not separable. Two in-kind public benefits are pure cost with no revenue. N. Pierce Street carries a PERPETUAL maintenance obligation that outlives every exit modelled here.
A9: How to calibrate | B9: Two external checks, both on the Returns sheet. (1) Peak debt vs the reported $380M commitment — if peak debt sits far from ~100%, the cost assumptions are wrong, not the loan. (2) Aubrey + Evo blended $/unit against Cortland's ~$1B for ~1,320 Arlington units in May 2022. Move assumptions to satisfy those two, not to reach a target IRR.
A10: Known soft spots | B10: 1) Land basis is a placeholder — pull the recorded deed. 2) The $380M loan is press-reported, not verified to the recorded deed of trust. 3) Real estate tax is an assumption but should not be: Arlington publishes assessment history per RPC. 4) The affordable housing amount is a decision variable, not a constant — SP445 Condition #42 deliberately fixes no number.
A11: Sheets | B11: Assumptions -> Program -> DevBudget -> Ops -> CashFlow -> Waterfall -> Returns. CashFlow is monthly, 90 periods from Jul-2016. Interest is capitalised and repaid inside 'Loan repayment', never as a cash line.
A12: Honest caveat | B12: This model does not tell you what Penzance earned. It tells you what a deal with this program, these obligations and this timeline earns under stated assumptions. That distinction is the entire point of the benchmark: the structure is fact, the pricing is declared.

Sheet Assumptions
A1: THE HIGHLANDS — ASSUMPTIONS
A2: Blue = editable input. Every value on this sheet is an ASSUMPTION unless the Source column cites SP #445.
A4: Assumption | B4: Value | C4: Unit | D4: Source / rationale
A6: TIMELINE
A7: Model start (month 1) | B7: 40787 | C7: date | D7: FACT: land acquired 2011-09-30 [Arlington assessments, deed 4491/2257]. Corroborates Kusturiss's 'eleven years' at exit.
A8: Model horizon | B8: 160 | C8: months | D8: Through Dec-2024; the condo sellout tail runs to Jun-2024 [FACT].
A9: Construction start (month #) | B9: 80 | C9: month# | D9: ASSUMPTION: Apr-2018 (month 80). Approval Feb-2017 + ~14 mo to permits/GMP. Replace with the Footing-to-Grade permit date.
A10: Construction duration | B10: 39 | C10: months | D10: ASSUMPTION: 39 mo. Lands delivery month 119 = Jul-2021, consistent with the staff report's 'Summer 2021' AND with the first recorded condo closing, 2021-08-30 [FACT].
A12: DEVELOPMENT COST
A13: Land basis (fee parcels) | B13: 67000000 | C13: $ | D13: FACT. $67,000,000 recorded 2011-09-30, deed 4491/2257, one price across fee parcels -008/-009/-010/-011/-018. County parcels were ground-leased, not purchased.
A14: Hard cost per sf of GFA | B14: 255 | C14: $/sf | D14: ASSUMPTION. DC-metro concrete residential high-rise, 2018-21 procurement. Excludes below-grade garage (priced per space below).
A15: Garage hard cost per space | B15: 32000 | C15: $/space | D15: ASSUMPTION. Below-grade structured parking; garage GFA is excluded from the FAR cap [SP445 FACT] so it is priced separately.
A16: Fire Station 10 cost per sf | B16: 400 | C16: $/sf | D16: ASSUMPTION. Essential-facility construction premium on 18,637 sf [SP445 FACT]. In-kind public benefit — cost with no revenue.
A17: Rosslyn Highlands Park | B17: 8000000 | C17: $ | D17: ASSUMPTION. In-kind benefit; County delivered schematic design [SP445 FACT].
A18: N. Pierce Street construction | B18: 6000000 | C18: $ | D18: ASSUMPTION. New public street, developer-built [SP445 FACT].
A19: Soft costs (% of hard) | B19: 0.17 | C19: % | D19: ASSUMPTION. A&E, legal, entitlement carry, marketing, insurance, financing fees.
A20: Contingency (% of hard) | B20: 0.05 | C20: % | D20: ASSUMPTION.
A21: Developer fee (% of cost) | B21: 0.035 | C21: % | D21: ASSUMPTION. Not public — Penzance/Baupost JV term.
A23: DEBT
A24: Construction loan commitment | B24: 380000000 | C24: $ | D24: PRESS-REPORTED (Mack Real Estate Credit Strategies). NOT yet verified to the recorded deed of trust — do that before relying on it.
A25: Blended all-in interest rate | B25: 0.065 | C25: % | D25: ASSUMPTION. Construction-loan pricing not public. Interest is capitalised during construction.
A26: Max loan-to-cost | B26: 0.65 | C26: % | D26: ASSUMPTION. Equity funds first, then loan draws — standard construction structure.
A28: RENTAL OPERATIONS
A29: Aubrey — avg rent per unit / month | B29: 3522 | C29: $/mo | D29: DERIVED, not assumed. Solved so NOI ties to the assessor's own implied NOI (1/1/2022 assessment x Arlington's guideline loaded cap of 5.15%). Above the county-wide high-rise top-of-range, as brand-new Rosslyn product should be.
A30: Evo — avg rent per unit / month | B30: 3273 | C30: $/mo | D30: DERIVED, same method. Lower than Aubrey: Evo skews small (49 studios + 52 Jr-1BR, only 2 3BR) [SP445 FACT].
A31: Other income (% of GPR) | B31: 0.04 | C31: % | D31: ASSUMPTION. Parking, fees, pet rent.
A32: Stabilised vacancy + credit loss | B32: 0.08 | C32: % | D32: FACT. Arlington 2022 Guidebook, High-Rise market: 8%, including vacancy, rent loss and concessions. The 2023 edition shows 6%.
A33: Operating expense per unit / yr | B33: 7511 | C33: $/unit | D33: FACT. Arlington 2022 Guidebook, High-Rise effective age 2010+: $7,511/unit, excluding real estate tax. The earlier $11,000 assumption was ~50% too high.
A34: Parking income per space / month | B34: 150 | C34: $/mo | D34: FACT. Arlington Guidebook garage parking $50-$150/mo; top of range for new Metro-adjacent product.
A35: Parking spaces per unit | B35: 0.8 | C35: ratio | D35: FACT [SP445]: residential parking ratio 0.80 spaces/unit.
A36: Aubrey assessed value 1/1/2022 | B36: 229060900 | C36: $ | D36: FACT. Sum of the 7 ground-leased Phase I parcels [Arlington assessments].
A37: Evo assessed value 1/1/2022 | B37: 290055300 | C37: $ | D37: FACT. RPC 16-033-025 [Arlington assessments].
A38: Effective RE tax rate | B38: 0.0113 | C38: % | D38: DERIVED from actual billing: RPC 16-033-012, $567,034.08 semi-annual on $99,617,600 assessed, annualised. Includes the Rosslyn BID special district. Verify against a full tax bill.
A39: Lease-up pace | B39: 25 | C39: units/mo | D39: ASSUMPTION. Applied to each tower from its delivery month.
A40: Evo delivery lag after Aubrey | B40: 2 | C40: months | D40: ASSUMPTION. East Building is the larger/taller structure.
A42: RETAIL
A43: Retail rent | B43: 48 | C43: $/sf | D43: ASSUMPTION, NNN. Anchor is CVS in the West Building [SP445 FACT].
A44: Retail stabilised occupancy | B44: 0.9 | C44: % | D44: ASSUMPTION. Deliberately below 100%: the East Building fitness lease died in COVID and that space reverted to residential [SP445 FACT].
A46: CONDO SELLOUT (PIERCE)
A47: Gross sellout (actual) | B47: 190186220 | C47: $ | D47: FACT. Sum of the first arms-length sale on each of 102 units (2 of 104 never transferred). Every unit scraped individually from Arlington assessments.
...

Sheet Program
A1: PROGRAM — FACTS FROM SP #445
A2: Green = fact from inputs/highlands.toml. Do not edit here; edit the TOML and rebuild.
A4: Item | B4: Pierce | C4: Evo | D4: Aubrey | E4: Source
A5: Units | B5: 104 | C5: 455 | D5: 331 | E5: SP445 2018 p.40 / 2020 Fig.5
A6: Tenure | B6: For sale | C6: Rental | D6: Rental | E6: SP445 2018 p.40 labels tables CONDO / APARTMENT
A7: Building | B7: East / North | C7: East / South | D7: West | E7: SP445 2018 pp.39-40
A8: Residential GFA (sf) | C8: 754567 | D8: 404864 | E8: SP445 2020 Fig.5 (East shared by Pierce+Evo)
A9: Retail GFA (sf) | C9: 13891 | D9: 9788 | E9: SP445 2020 Fig.5
A10: Stories | B10: 27 | C10: 27 | D10: 23 | E10: SP445 2017 pp.11-12
A12: PROJECT TOTALS
A13: Total units | B13: 890 | E13: 104 + 455 + 331 [SP445]
A14: Total GFA (sf) | B14: 1183110 | E14: SP445 2020 Fig.5
A15: Total residential GFA (sf) | B15: 1159431 | E15: SP445 2020 Fig.5
A16: Total retail GFA (sf) | B16: 23679 | E16: SP445 2020 Fig.5
A17: Fire Station GFA (sf) | B17: 18637 | E17: SP445 — in-kind public benefit, no revenue
A18: Total parking spaces | B18: 1037 | E18: SP445 2020 Fig.5
A19: Site area (sf) | B19: 118311 | E19: SP445 2017 p.11
A20: FAR | B20: 10 | E20: Approved AT the 10.0 cap — no residual density

Sheet DevBudget
A1: DEVELOPMENT BUDGET
A2: All formulas. Drivers live on Assumptions; quantities on Program.
A4: Line item | B4: Amount | C4: Per unit | D4: % of total | E4: Basis
A5: Land basis | B5: =Assumptions!$B$13 | C5: =B5/Program!$B$13 | D5: =IFERROR(B5/$B$17,0) | E5: Assumption — replace with recorded deed consideration
A6: Hard cost — buildings | B6: =Assumptions!$B$14*Program!$B$14 | C6: =B6/Program!$B$13 | D6: =IFERROR(B6/$B$17,0) | E6: hard $/sf x total GFA
A7: Hard cost — garage | B7: =Assumptions!$B$15*Program!$B$18 | C7: =B7/Program!$B$13 | D7: =IFERROR(B7/$B$17,0) | E7: $/space x 1,037 spaces (garage GFA is FAR-excluded)
A8: Fire Station 10 | B8: =Assumptions!$B$16*Program!$B$17 | C8: =B8/Program!$B$13 | D8: =IFERROR(B8/$B$17,0) | E8: IN-KIND public benefit — cost, no revenue
A9: Rosslyn Highlands Park | B9: =Assumptions!$B$17 | C9: =B9/Program!$B$13 | D9: =IFERROR(B9/$B$17,0) | E9: IN-KIND public benefit
A10: N. Pierce Street | B10: =Assumptions!$B$18 | C10: =B10/Program!$B$13 | D10: =IFERROR(B10/$B$17,0) | E10: IN-KIND public benefit — plus perpetual maintenance
A11: Subtotal — hard costs | B11: =SUM(B6:B10) | C11: =B11/Program!$B$13 | D11: =IFERROR(B11/$B$17,0)
A12: Soft costs | B12: =Assumptions!$B$19*B11 | C12: =B12/Program!$B$13 | D12: =IFERROR(B12/$B$17,0) | E12: % of hard
A13: Contingency | B13: =Assumptions!$B$20*B11 | C13: =B13/Program!$B$13 | D13: =IFERROR(B13/$B$17,0) | E13: % of hard
A14: Public obligations (cash) | B14: =Assumptions!$B$76 | C14: =B14/Program!$B$13 | D14: =IFERROR(B14/$B$17,0) | E14: SP445 conditions — fact, except the AH amount
A15: Subtotal before fee | B15: =B5+B11+B12+B13+B14 | C15: =B15/Program!$B$13 | D15: =IFERROR(B15/$B$17,0)
A16: Developer fee | B16: =Assumptions!$B$21*B15 | C16: =B16/Program!$B$13 | D16: =IFERROR(B16/$B$17,0) | E16: % of cost before fee
A17: TOTAL DEV COST (ex interest) | B17: =B15+B16 | C17: =B17/Program!$B$13 | D17: =IFERROR(B17/$B$17,0) | E17: Interest is capitalised in CashFlow, not budgeted here
A19: Equity commitment | B19: =B17*(1-Assumptions!$B$26)
A20: Loan sized at LTC | B20: =B17*Assumptions!$B$26
A21: Loan commitment (press-reported) | B21: =Assumptions!$B$24
A22: Implied LTC at reported commitment | B22: =IFERROR(B21/B17,0)
A23: CALIBRATION: the reported $380M commitment against this budget implies the LTC above. If that lands far from a market 60-70%, the hard-cost assumption is wrong, not the loan.

Sheet Ops
A1: STABILISED PRO FORMA — RENTAL ASSETS
A2: Static stabilised year. CashFlow models the monthly ramp separately; exit values are struck off this sheet.
A4: Line | B4: Aubrey (West) | C4: Evo (East/South) | D4: Note
A5: Units | B5: =Program!$D$5 | C5: =Program!$C$5 | D5: Fact [SP445]
A6: Gross potential rent | B6: =B5*Assumptions!$B$29*12 | C6: =C5*Assumptions!$B$30*12 | D6: units x rent x 12
A7: Other income | B7: =B6*Assumptions!$B$31 | C7: =C6*Assumptions!$B$31 | D7: % of GPR
A8: Vacancy & credit loss | B8: =-(B6+B7)*Assumptions!$B$32 | C8: =-(C6+C7)*Assumptions!$B$32
A9: Parking income | B9: =B5*Assumptions!$B$35*Assumptions!$B$34*12 | C9: =C5*Assumptions!$B$35*Assumptions!$B$34*12 | D9: Arlington Guidebook garage rate x the SP445 0.80 spaces/unit ratio
A10: Retail revenue (NNN) | B10: =Program!$D$9*Assumptions!$B$43*Assumptions!$B$44 | C10: =Program!$C$9*Assumptions!$B$43*Assumptions!$B$44 | D10: West retail = CVS anchor; East retail follows Evo
A11: Effective gross income | B11: =SUM(B6:B10) | C11: =SUM(C6:C10)
A12: Operating expenses | B12: =-B5*Assumptions!$B$33 | C12: =-C5*Assumptions!$B$33 | D12: Excludes real estate tax
A13: Real estate tax | B13: =-Assumptions!$B$36*Assumptions!$B$38 | C13: =-Assumptions!$B$37*Assumptions!$B$38 | D13: FACT-BASED: 1/1/2022 assessed value x effective rate derived from actual billing
A14: NOI BEFORE real estate tax | B14: =B11+B12 | C14: =C11+C12 | D14: This is the figure Arlington's LOADED cap rate applies to. Do not compare it to a conventional after-tax cap.
A15: NOI after real estate tax | B15: =B11+B12+B13 | C15: =C11+C12+C13 | D15: Cash-flow NOI, used in CashFlow
A16: NOI margin | B16: =IFERROR(B15/B11,0) | C16: =IFERROR(C15/C11,0) | D16: Sanity check — 55-65% is normal
A18: Exit price | B18: =Assumptions!$B$56 | C18: =Assumptions!$B$55 | D18: Evo = FACT (recorded 2022-07-12). Aubrey = DERIVED from the Evo sale/assessment ratio — leasehold, so no price is recorded.
A19: Exit $ per unit | B19: =IFERROR(B18/B5,0) | C19: =IFERROR(C18/C5,0) | D19: Blended $764k/unit across 784 units — lands on the ~$758k Cortland figure.
A20: IMPLIED LOADED CAP (on pre-tax NOI) | B20: =IFERROR(B14/B18,0) | C20: =IFERROR(C14/C18,0) | D20: Apples-to-apples with Arlington's 5.15% guideline. Both towers land ~4.43-4.46%, i.e. ~70bp INSIDE the county guideline for their class.
A21: IMPLIED BASE CAP | B21: =B20-Assumptions!$B$54 | C21: =C20-Assumptions!$B$54 | D21: Loaded cap less the effective tax rate — the number a broker would quote. ~3.4%.
A22: Arlington guideline loaded cap | B22: =Assumptions!$B$53 | C22: =Assumptions!$B$53 | D22: High-Rise / Metro / 2010+ [FACT]
A23: Exit value (net of sale costs) | B23: =B18*(1-Assumptions!$B$57) | C23: =C18*(1-Assumptions!$B$57)
A25: PIERCE — CONDO SELLOUT
A26: Units declared | B26: =Program!$B$5 | D26: FACT [SP445 2018 p.40] — 104 declared
A27: Units actually sold | B27: =Assumptions!$B$48 | D27: FACT — 2 of 104 never transferred
A28: Gross sellout (ACTUAL) | B28: =Assumptions!$B$47 | D28: FACT — every unit scraped from Arlington assessments; see Sellout sheet
A29: Avg price per unit | B29: =IFERROR(B28/B27,0) | D29: Actual: median $1,774,000; range $822,000-$3,920,000
A30: Selling costs | B30: =-B28*Assumptions!$B$49
A31: NET SELLOUT PROCEEDS | B31: =B28+B30

Sheet Sellout
A1: PIERCE CONDO SELLOUT — ACTUAL RECORDED CLOSINGS
A2: Every one of the 104 declared units was looked up individually in the Arlington assessment records. 102 transferred; 2 never did. Dates and prices are the first arms-length sale on each unit.
A3: This replaces the assumed 8-units/month curve entirely. Actual sellout ran 34 months, not 13.
A5: Month # | B5: Year-month | C5: Units closed | D5: Gross proceeds | E5: Cumulative units
A6: 120 | B6: 2021-08 | C6: 1 | D6: 2056400 | E6: 1
A7: 121 | B7: 2021-09 | C7: 6 | D7: 8109000 | E7: 7
A8: 122 | B8: 2021-10 | C8: 3 | D8: 6243000 | E8: 10
A9: 123 | B9: 2021-11 | C9: 8 | D9: 16820000 | E9: 18
A10: 124 | B10: 2021-12 | C10: 10 | D10: 22430000 | E10: 28
A11: 125 | B11: 2022-01 | C11: 12 | D11: 23646000 | E11: 40
A12: 126 | B12: 2022-02 | C12: 5 | D12: 11617000 | E12: 45
A13: 127 | B13: 2022-03 | C13: 3 | D13: 4729000 | E13: 48
A14: 128 | B14: 2022-04 | C14: 3 | D14: 7200000 | E14: 51
A15: 129 | B15: 2022-05 | C15: 1 | D15: 2750000 | E15: 52
A16: 130 | B16: 2022-06 | C16: 2 | D16: 2407000 | E16: 54
A17: 131 | B17: 2022-07 | C17: 3 | D17: 5735000 | E17: 57
... A35: 154 | B35: 2024-06 | C35: 2 | D35: 3975000 | E35: 102
A36: TOTAL | C36: =SUM(C6:C35) | D36: =SUM(D6:D35)
A38: Peak absorption was Dec-2021 / Jan-2022 (10 and 12 closings). The long tail through Jun-2024 is what an assumed constant pace cannot capture, and it matters: proceeds arriving 2-3 years late are worth materially less.

Sheet CashFlow
A1: MONTHLY CASH FLOW | AE1: Aubrey delivery (month #)
A2: Interest is capitalised into the loan balance, so it is never a cash line; it is repaid inside 'Loan repayment'. | AE2: =Assumptions!$B$9+Assumptions!$B$10
A3: Equity funds first up to its commitment, then the loan draws — standard construction structure. | AE3: Evo / Pierce delivery (month #)
AE4: =$AE$2+Assumptions!$B$40
A5: Month # | B5: Date | C5: Phase | D5: Curve wt | E5: Curve share | F5: Land | G5: Hard - buildings | H5: Hard - garage | I5: Fire Station | J5: Park + street | K5: Soft costs | L5: Contingency | M5: Public obligations | N5: Developer fee | O5: TOTAL DEV COST | P5: Cum dev cost | Q5: Equity draw | R5: Cum equity | S5: Loan draw | T5: Loan bal BOP | U5: Interest capitalised | V5: Loan repayment | W5: Loan bal EOP | X5: Aubrey NOI | Y5: Evo NOI | Z5: Pierce net proceeds | AA5: Asset sale (net) | AB5: UNLEVERED CF | AC5: EQUITY CF | AE5: Curve weight total
A6: 1 | B6: =EDATE(Assumptions!$B$7,A6-1) | C6: =IF(A6<Assumptions!$B$9,"Pre-dev",IF(A6<$AE$2,"Construction",IF(A6<=Assumptions!$B$59,"Lease-up / exit","Tail"))) | D6: =IF(AND(A6>=Assumptions!$B$9,A6<$AE$2),(A6-Assumptions!$B$9+1)*($AE$2-A6),0) | E6: =IFERROR(D6/$AE$6,0) | F6: =IF(A6=1,DevBudget!$B$5,0) | G6: =E6*DevBudget!$B$6 | H6: =E6*DevBudget!$B$7 | I6: =E6*DevBudget!$B$8 | J6: =E6*(DevBudget!$B$9+DevBudget!$B$10) | K6: =E6*DevBudget!$B$12 | L6: =E6*DevBudget!$B$13 | M6: =IF(A6=Assumptions!$B$9,Assumptions!$B$69+Assumptions!$B$72,0)+IF(A6=$AE$4,Assumptions!$B$70+Assumptions!$B$71+Assumptions!$B$73,0) | N6: =E6*DevBudget!$B$16 | O6: =SUM(F6:N6) | P6: =0+O6 | Q6: =MIN(O6,MAX(0,DevBudget!$B$19-0)) | R6: =0+Q6 | S6: =MIN(MAX(0,O6-Q6),MAX(0,Assumptions!$B$24-T6-U6)) | T6: =0 | U6: =T6*Assumptions!$B$25/12 | V6: =MIN(T6+U6+S6,MAX(0,Z6+AA6)) | W6: =T6+S6+U6-V6 | X6: =IF(AND(A6>=$AE$2,A6<=Assumptions!$B$58),(MIN(Program!$D$5,MAX(0,(A6-$AE$2+1)*Assumptions!$B$39))*Assumptions!$B$29*(1+Assumptions!$B$31)*(1-Assumptions!$B$32)+Program!$D$9*Assumptions!$B$43*Assumptions!$B$44/12+Program!$D$5*Assumptions!$B$35*Assumptions!$B$34-Program!$D$5*Assumptions!$B$33/12-Assumptions!$B$36*Assumptions!$B$38/12),0) | Y6: =IF(AND(A6>=$AE$4,A6<=Assumptions!$B$59),(MIN(Program!$C$5,MAX(0,(A6-$AE$4+1)*Assumptions!$B$39))*Assumptions!$B$30*(1+Assumptions!$B$31)*(1-Assumptions!$B$32)+Program!$C$9*Assumptions!$B$43*Assumptions!$B$44/12+Program!$C$5*Assumptions!$B$35*Assumptions!$B$34-Program!$C$5*Assumptions!$B$33/12-Assumptions!$B$37*Assumptions!$B$38/12),0) | Z6: =SUMIF(Sellout!$A$6:$A$35,A6,Sellout!$D$6:$D$35)*(1-Assumptions!$B$49) | AA6: =IF(A6=Assumptions!$B$58,Ops!$B$23,0)+IF(A6=Assumptions!$B$59,Ops!$C$23,0) | AB6: =-O6+X6+Y6+Z6+AA6 | AC6: =AB6+S6-V6 | AE6: =SUM(D6:D165)
A7: 2 | B7: =EDATE(Assumptions!$B$7,A7-1) | C7: =IF(A7<Assumptions!$B$9,"Pre-dev",IF(A7<$AE$2,"Construction",IF(A7<=Assumptions!$B$59,"Lease-up / exit","Tail"))) | D7: =IF(AND(A7>=Assumptions!$B$9,A7<$AE$2),(A7-Assumptions!$B$9+1)*($AE$2-A7),0) | E7: =IFERROR(D7/$AE$6,0) | F7: =IF(A7=1,DevBudget!$B$5,0) | G7: =E7*DevBudget!$B$6 | H7: =E7*DevBudget!$B$7 | I7: =E7*DevBudget!$B$8 | J7: =E7*(DevBudget!$B$9+DevBudget!$B$10) | K7: =E7*DevBudget!$B$12 | L7: =E7*DevBudget!$B$13 | M7: =IF(A7=Assumptions!$B$9,Assumptions!$B$69+Assumptions!$B$72,0)+IF(A7=$AE$4,Assumptions!$B$70+Assumptions!$B$71+Assumptions!$B$73,0) | N7: =E7*DevBudget!$B$16 | O7: =SUM(F7:N7) | P7: =P6+O7 | Q7: =MIN(O7,MAX(0,DevBudget!$B$19-R6)) | R7: =R6+Q7 | S7: =MIN(MAX(0,O7-Q7),MAX(0,Assumptions!$B$24-T7-U7)) | T7: =W6 | U7: =T7*Assumptions!$B$25/12 | V7: =MIN(T7+U7+S7,MAX(0,Z7+AA7)) | W7: =T7+S7+U7-V7 | X7: =IF(AND(A7>=$AE$2,A7<=Assumptions!$B$58),(MIN(Program!$D$5,MAX(0,(A7-$AE$2+1)*Assumptions!$B$39))*Assumptions!$B$29*(1+Assumptions!$B$31)*(1-Assumptions!$B$32)+Program!$D$9*Assumptions!$B$43*Assumptions!$B$44/12+Program!$D$5*Assumptions!$B$35*Assumptions!$B$34-Program!$D$5*Assumptions!$B$33/12-Assumptions!$B$36*Assumptions!$B$38/12),0) | Y7: =IF(AND(A7>=$AE$4,A7<=Assumptions!$B$59),(MIN(Program!$C$5,MAX(0,(A7-$AE$4+1)*Assumptions!$B$39))*Assumptions!$B$30*(1+Assumptions!$B$31)*(1-Assumptions!$B$32)+Program!$C$9*Assumptions!$B$43*Assumptions!$B$44/12+Program!$C$5*Assumptions!$B$35*Assumptions!$B$34-Program!$C$5*Assumptions!$B$33/12-Assumptions!$B$37*Assumptions!$B$38/12),0) | Z7: =SUMIF(Sellout!$A$6:$A$35,A7,Sellout!$D$6:$D$35)*(1-Assumptions!$B$49) | AA7: =IF(A7=Assumptions!$B$58,Ops!$B$23,0)+IF(A7=Assumptions!$B$59,Ops!$C$23,0) | AB7: =-O7+X7+Y7+Z7+AA7 | AC7: =AB7+S7-V7
A8: 3 | B8: =EDATE(Assumptions!$B$7,A8-1) | C8: =IF(A8<Assumptions!$B$9,"Pre-dev",IF(A8<$AE$2,"Construction",IF(A8<=Assumptions!$B$59,"Lease-up / exit","Tail"))) | D8: =IF(AND(A8>=Assumptions!$B$9,A8<$AE$2),(A8-Assumptions!$B$9+1)*($AE$2-A8),0) | E8: =IFERROR(D8/$AE$6,0) | F8: =IF(A8=1,DevBudget!$B$5,0) | G8: =E8*DevBudget!$B$6 | H8: =E8*DevBudget!$B$7 | I8: =E8*DevBudget!$B$8 | J8: =E8*(DevBudget!$B$9+DevBudget!$B$10) | K8: =E8*DevBudget!$B$12 | L8: =E8*DevBudget!$B$13 | M8: =IF(A8=Assumptions!$B$9,Assumptions!$B$69+Assumptions!$B$72,0)+IF(A8=$AE$4,Assumptions!$B$70+Assumptions!$B$71+Assumptions!$B$73,0) | N8: =E8*DevBudget!$B$16 | O8: =SUM(F8:N8) | P8: =P7+O8 | Q8: =MIN(O8,MAX(0,DevBudget!$B$19-R7)) | R8: =R7+Q8 | S8: =MIN(MAX(0,O8-Q8),MAX(0,Assumptions!$B$24-T8-U8)) | T8: =W7 | U8: =T8*Assumptions!$B$25/12 | V8: =MIN(T8+U8+S8,MAX(0,Z8+AA8)) | W8: =T8+S8+U8-V8 | X8: =IF(AND(A8>=$AE$2,A8<=Assumptions!$B$58),(MIN(Program!$D$5,MAX(0,(A8-$AE$2+1)*Assumptions!$B$39))*Assumptions!$B$29*(1+Assumptions!$B$31)*(1-Assumptions!$B$32)+Program!$D$9*Assumptions!$B$43*Assumptions!$B$44/12+Program!$D$5*Assumptions!$B$35*Assumptions!$B$34-Program!$D$5*Assumptions!$B$33/12-Assumptions!$B$36*Assumptions!$B$38/12),0) | Y8: =IF(AND(A8>=$AE$4,A8<=Assumptions!$B$59),(MIN(Program!$C$5,MAX(0,(A8-$AE$4+1)*Assumptions!$B$39))*Assumptions!$B$30*(1+Assumptions!$B$31)*(1-Assumptions!$B$32)+Program!$C$9*Assumptions!$B$43*Assumptions!$B$44/12+Program!$C$5*Assumptions!$B$35*Assumptions!$B$34-Program!$C$5*Assumptions!$B$33/12-Assumptions!$B$37*Assumptions!$B$38/12),0) | Z8: =SUMIF(Sellout!$A$6:$A$35,A8,Sellout!$D$6:$D$35)*(1-Assumptions!$B$49) | AA8: =IF(A8=Assumptions!$B$58,Ops!$B$23,0)+IF(A8=Assumptions!$B$59,Ops!$C$23,0) | AB8: =-O8+X8+Y8+Z8+AA8 | AC8: =AB8+S8-V8
A9: 4 | B9: =EDATE(Assumptions!$B$7,A9-1) | C9: =IF(A9<Assumptions!$B$9,"Pre-dev",IF(A9<$AE$2,"Construction",IF(A9<=Assumptions!$B$59,"Lease-up / exit","Tail"))) | D9: =IF(AND(A9>=Assumptions!$B$9,A9<$AE$2),(A9-Assumptions!$B$9+1)*($AE$2-A9),0) | E9: =IFERROR(D9/$AE$6,0) | F9: =IF(A9=1,DevBudget!$B$5,0) | G9: =E9*DevBudget!$B$6 | H9: =E9*DevBudget!$B$7 | I9: =E9*DevBudget!$B$8 | J9: =E9*(DevBudget!$B$9+DevBudget!$B$10) | K9: =E9*DevBudget!$B$12 | L9: =E9*DevBudget!$B$13 | M9: =IF(A9=Assumptions!$B$9,Assumptions!$B$69+Assumptions!$B$72,0)+IF(A9=$AE$4,Assumptions!$B$70+Assumptions!$B$71+Assumptions!$B$73,0) | N9: =E9*DevBudget!$B$16 | O9: =SUM(F9:N9) | P9: =P8+O9 | Q9: =MIN(O9,MAX(0,DevBudget!$B$19-R8)) | R9: =R8+Q9 | S9: =MIN(MAX(0,O9-Q9),MAX(0,Assumptions!$B$24-T9-U9)) | T9: =W8 | U9: =T9*Assumptions!$B$25/12 | V9: =MIN(T9+U9+S9,MAX(0,Z9+AA9)) | W9: =T9+S9+U9-V9 | X9: =IF(AND(A9>=$AE$2,A9<=Assumptions!$B$58),(MIN(Program!$D$5,MAX(0,(A9-$AE$2+1)*Assumptions!$B$39))*Assumptions!$B$29*(1+Assumptions!$B$31)*(1-Assumptions!$B$32)+Program!$D$9*Assumptions!$B$43*Assumptions!$B$44/12+Program!$D$5*Assumptions!$B$35*Assumptions!$B$34-Program!$D$5*Assumptions!$B$33/12-Assumptions!$B$36*Assumptions!$B$38/12),0) | Y9: =IF(AND(A9>=$AE$4,A9<=Assumptions!$B$59),(MIN(Program!$C$5,MAX(0,(A9-$AE$4+1)*Assumptions!$B$39))*Assumptions!$B$30*(1+Assumptions!$B$31)*(1-Assumptions!$B$32)+Program!$C$9*Assumptions!$B$43*Assumptions!$B$44/12+Program!$C$5*Assumptions!$B$35*Assumptions!$B$34-Program!$C$5*Assumptions!$B$33/12-Assumptions!$B$37*Assumptions!$B$38/12),0) | Z9: =SUMIF(Sellout!$A$6:$A$35,A9,Sellout!$D$6:$D$35)*(1-Assumptions!$B$49) | AA9: =IF(A9=Assumptions!$B$58,Ops!$B$23,0)+IF(A9=Assumptions!$B$59,Ops!$C$23,0) | AB9: =-O9+X9+Y9+Z9+AA9 | AC9: =AB9+S9-V9
A10: 5 | B10: =EDATE(Assumptions!$B$7,A10-1) | C10: =IF(A10<Assumptions!$B$9,"Pre-dev",IF(A10<$AE$2,"Construction",IF(A10<=Assumptions!$B$59,"Lease-up / exit","Tail"))) | D10: =IF(AND(A10>=Assumptions!$B$9,A10<$AE$2),(A10-Assumptions!$B$9+1)*($AE$2-A10),0) | E10: =IFERROR(D10/$AE$6,0) | F10: =IF(A10=1,DevBudget!$B$5,0) | G10: =E10*DevBudget!$B$6 | H10: =E10*DevBudget!$B$7 | I10: =E10*DevBudget!$B$8 | J10: =E10*(DevBudget!$B$9+DevBudget!$B$10) | K10: =E10*DevBudget!$B$12 | L10: =E10*DevBudget!$B$13 | M10: =IF(A10=Assumptions!$B$9,Assumptions!$B$69+Assumptions!$B$72,0)+IF(A10=$AE$4,Assumptions!$B$70+Assumptions!$B$71+Assumptions!$B$73,0) | N10: =E10*DevBudget!$B$16 | O10: =SUM(F10:N10) | P10: =P9+O10 | Q10: =MIN(O10,MAX(0,DevBudget!$B$19-R9)) | R10: =R9+Q10 | S10: =MIN(MAX(0,O10-Q10),MAX(0,Assumptions!$B$24-T10-U10)) | T10: =W9 | U10: =T10*Assumptions!$B$25/12 | V10: =MIN(T10+U10+S10,MAX(0,Z10+AA10)) | W10: =T10+S10+U10-V10 | X10: =IF(AND(A10>=$AE$2,A10<=Assumptions!$B$58),(MIN(Program!$D$5,MAX(0,(A10-$AE$2+1)*Assumptions!$B$39))*Assumptions!$B$29*(1+Assumptions!$B$31)*(1-Assumptions!$B$32)+Program!$D$9*Assumptions!$B$43*Assumptions!$B$44/12+Program!$D$5*Assumptions!$B$35*Assumptions!$B$34-Program!$D$5*Assumptions!$B$33/12-Assumptions!$B$36*Assumptions!$B$38/12),0) | Y10: =IF(AND(A10>=$AE$4,A10<=Assumptions!$B$59),(MIN(Program!$C$5,MAX(0,(A10-$AE$4+1)*Assumptions!$B$39))*Assumptions!$B$30*(1+Assumptions!$B$31)*(1-Assumptions!$B$32)+Program!$C$9*Assumptions!$B$43*Assumptions!$B$44/12+Program!$C$5*Assumptions!$B$35*Assumptions!$B$34-Program!$C$5*Assumptions!$B$33/12-Assumptions!$B$37*Assumptions!$B$38/12),0) | Z10: =SUMIF(Sellout!$A$6:$A$35,A10,Sellout!$D$6:$D$35)*(1-Assumptions!$B$49) | AA10: =IF(A10=Assumptions!$B$58,Ops!$B$23,0)+IF(A10=Assumptions!$B$59,Ops!$C$23,0) | AB10: =-O10+X10+Y10+Z10+AA10 | AC10: =AB10+S10-V10
A11: 6 | B11: =EDATE(Assumptions!$B$7,A11-1) | C11: =IF(A11<Assumptions!$B$9,"Pre-dev",IF(A11<$AE$2,"Construction",IF(A11<=Assumptions!$B$59,"Lease-up / exit","Tail"))) | D11: =IF(AND(A11>=Assumptions!$B$9,A11<$AE$2),(A11-Assumptions!$B$9+1)*($AE$2-A11),0) | E11: =IFERROR(D11/$AE$6,0) | F11: =IF(A11=1,DevBudget!$B$5,0) | G11: =E11*DevBudget!$B$6 | H11: =E11*DevBudget!$B$7 | I11: =E11*DevBudget!$B$8 | J11: =E11*(DevBudget!$B$9+DevBudget!$B$10) | K11: =E11*DevBudget!$B$12 | L11: =E11*DevBudget!$B$13 | M11: =IF(A11=Assumptions!$B$9,Assumptions!$B$69+Assumptions!$B$72,0)+IF(A11=$AE$4,Assumptions!$B$70+Assumptions!$B$71+Assumptions!$B$73,0) | N11: =E11*DevBudget!$B$16 | O11: =SUM(F11:N11) | P11: =P10+O11 | Q11: =MIN(O11,MAX(0,DevBudget!$B$19-R10)) | R11: =R10+Q11 | S11: =MIN(MAX(0,O11-Q11),MAX(0,Assumptions!$B$24-T11-U11)) | T11: =W10 | U11: =T11*Assumptions!$B$25/12 | V11: =MIN(T11+U11+S11,MAX(0,Z11+AA11)) | W11: =T11+S11+U11-V11 | X11: =IF(AND(A11>=$AE$2,A11<=Assumptions!$B$58),(MIN(Program!$D$5,MAX(0,(A11-$AE$2+1)*Assumptions!$B$39))*Assumptions!$B$29*(1+Assumptions!$B$31)*(1-Assumptions!$B$32)+Program!$D$9*Assumptions!$B$43*Assumptions!$B$44/12+Program!$D$5*Assumptions!$B$35*Assumptions!$B$34-Program!$D$5*Assumptions!$B$33/12-Assumptions!$B$36*Assumptions!$B$38/12),0) | Y11: =IF(AND(A11>=$AE$4,A11<=Assumptions!$B$59),(MIN(Program!$C$5,MAX(0,(A11-$AE$4+1)*Assumptions!$B$39))*Assumptions!$B$30*(1+Assumptions!$B$31)*(1-Assumptions!$B$32)+Program!$C$9*Assumptions!$B$43*Assumptions!$B$44/12+Program!$C$5*Assumptions!$B$35*Assumptions!$B$34-Program!$C$5*Assumptions!$B$33/12-Assumptions!$B$37*Assumptions!$B$38/12),0) | Z11: =SUMIF(Sellout!$A$6:$A$35,A11,Sellout!$D$6:$D$35)*(1-Assumptions!$B$49) | AA11: =IF(A11=Assumptions!$B$58,Ops!$B$23,0)+IF(A11=Assumptions!$B$59,Ops!$C$23,0) | AB11: =-O11+X11+Y11+Z11+AA11 | AC11: =AB11+S11-V11
A12: 7 | B12: =EDATE(Assumptions!$B$7,A12-1) | C12: =IF(A12<Assumptions!$B$9,"Pre-dev",IF(A12<$AE$2,"Construction",IF(A12<=Assumptions!$B$59,"Lease-up / exit","Tail"))) | D12: =IF(AND(A12>=Assumptions!$B$9,A12<$AE$2),(A12-Assumptions!$B$9+1)*($AE$2-A12),0) | E12: =IFERROR(D12/$AE$6,0) | F12: =IF(A12=1,DevBudget!$B$5,0) | G12: =E12*DevBudget!$B$6 | H12: =E12*DevBudget!$B$7 | I12: =E12*DevBudget!$B$8 | J12: =E12*(DevBudget!$B$9+DevBudget!$B$10) | K12: =E12*DevBudget!$B$12 | L12: =E12*DevBudget!$B$13 | M12: =IF(A12=Assumptions!$B$9,Assumptions!$B$69+Assumptions!$B$72,0)+IF(A12=$AE$4,Assumptions!$B$70+Assumptions!$B$71+Assumptions!$B$73,0) | N12: =E12*DevBudget!$B$16 | O12: =SUM(F12:N12) | P12: =P11+O12 | Q12: =MIN(O12,MAX(0,DevBudget!$B$19-R11)) | R12: =R11+Q12 | S12: =MIN(MAX(0,O12-Q12),MAX(0,Assumptions!$B$24-T12-U12)) | T12: =W11 | U12: =T12*Assumptions!$B$25/12 | V12: =MIN(T12+U12+S12,MAX(0,Z12+AA12)) | W12: =T12+S12+U12-V12 | X12: =IF(AND(A12>=$AE$2,A12<=Assumptions!$B$58),(MIN(Program!$D$5,MAX(0,(A12-$AE$2+1)*Assumptions!$B$39))*Assumptions!$B$29*(1+Assumptions!$B$31)*(1-Assumptions!$B$32)+Program!$D$9*Assumptions!$B$43*Assumptions!$B$44/12+Program!$D$5*Assumptions!$B$35*Assumptions!$B$34-Program!$D$5*Assumptions!$B$33/12-Assumptions!$B$36*Assumptions!$B$38/12),0) | Y12: =IF(AND(A12>=$AE$4,A12<=Assumptions!$B$59),(MIN(Program!$C$5,MAX(0,(A12-$AE$4+1)*Assumptions!$B$39))*Assumptions!$B$30*(1+Assumptions!$B$31)*(1-Assumptions!$B$32)+Program!$C$9*Assumptions!$B$43*Assumptions!$B$44/12+Program!$C$5*Assumptions!$B$35*Assumptions!$B$34-Program!$C$5*Assumptions!$B$33/12-Assumptions!$B$37*Assumptions!$B$38/12),0) | Z12: =SUMIF(Sellout!$A$6:$A$35,A12,Sellout!$D$6:$D$35)*(1-Assumptions!$B$49) | AA12: =IF(A12=Assumptions!$B$58,Ops!$B$23,0)+IF(A12=Assumptions!$B$59,Ops!$C$23,0) | AB12: =-O12+X12+Y12+Z12+AA12 | AC12: =AB12+S12-V12
A13: 8 | B13: =EDATE(Assumptions!$B$7,A13-1) | C13: =IF(A13<Assumptions!$B$9,"Pre-dev",IF(A13<$AE$2,"Construction",IF(A13<=Assumptions!$B$59,"Lease-up / exit","Tail"))) | D13: =IF(AND(A13>=Assumptions!$B$9,A13<$AE$2),(A13-Assumptions!$B$9+1)*($AE$2-A13),0) | E13: =IFERROR(D13/$AE$6,0) | F13: =IF(A13=1,DevBudget!$B$5,0) | G13: =E13*DevBudget!$B$6 | H13: =E13*DevBudget!$B$7 | I13: =E13*DevBudget!$B$8 | J13: =E13*(DevBudget!$B$9+DevBudget!$B$10) | K13: =E13*DevBudget!$B$12 | L13: =E13*DevBudget!$B$13 | M13: =IF(A13=Assumptions!$B$9,Assumptions!$B$69+Assumptions!$B$72,0)+IF(A13=$AE$4,Assumptions!$B$70+Assumptions!$B$71+Assumptions!$B$73,0) | N13: =E13*DevBudget!$B$16 | O13: =SUM(F13:N13) | P13: =P12+O13 | Q13: =MIN(O13,MAX(0,DevBudget!$B$19-R12)) | R13: =R12+Q13 | S13: =MIN(MAX(0,O13-Q13),MAX(0,Assumptions!$B$24-T13-U13)) | T13: =W12 | U13: =T13*Assumptions!$B$25/12 | V13: =MIN(T13+U13+S13,MAX(0,Z13+AA13)) | W13: =T13+S13+U13-V13 | X13: =IF(AND(A13>=$AE$2,A13<=Assumptions!$B$58),(MIN(Program!$D$5,MAX(0,(A13-$AE$2+1)*Assumptions!$B$39))*Assumptions!$B$29*(1+Assumptions!$B$31)*(1-Assumptions!$B$32)+Program!$D$9*Assumptions!$B$43*Assumptions!$B$44/12+Program!$D$5*Assumptions!$B$35*Assumptions!$B$34-Program!$D$5*Assumptions!$B$33/12-Assumptions!$B$36*Assumptions!$B$38/12),0) | Y13: =IF(AND(A13>=$AE$4,A13<=Assumptions!$B$59),(MIN(Program!$C$5,MAX(0,(A13-$AE$4+1)*Assumptions!$B$39))*Assumptions!$B$30*(1+Assumptions!$B$31)*(1-Assumptions!$B$32)+Program!$C$9*Assumptions!$B$43*Assumptions!$B$44/12+Program!$C$5*Assumptions!$B$35*Assumptions!$B$34-Program!$C$5*Assumptions!$B$33/12-Assumptions!$B$37*Assumptions!$B$38/12),0) | Z13: =SUMIF(Sellout!$A$6:$A$35,A13,Sellout!$D$6:$D$35)*(1-Assumptions!$B$49) | AA13: =IF(A13=Assumptions!$B$58,Ops!$B$23,0)+IF(A13=Assumptions!$B$59,Ops!$C$23,0) | AB13: =-O13+X13+Y13+Z13+AA13 | AC13: =AB13+S13-V13
A14: 9 | B14: =EDATE(Assumptions!$B$7,A14-1) | C14: =IF(A14<Assumptions!$B$9,"Pre-dev",IF(A14<$AE$2,"Construction",IF(A14<=Assumptions!$B$59,"Lease-up / exit","Tail"))) | D14: =IF(AND(A14>=Assumptions!$B$9,A14<$AE$2),(A14-Assumptions!$B$9+1)*($AE$2-A14),0) | E14: =IFERROR(D14/$AE$6,0) | F14: =IF(A14=1,DevBudget!$B$5,0) | G14: =E14*DevBudget!$B$6 | H14: =E14*DevBudget!$B$7 | I14: =E14*DevBudget!$B$8 | J14: =E14*(DevBudget!$B$9+DevBudget!$B$10) | K14: =E14*DevBudget!$B$12 | L14: =E14*DevBudget!$B$13 | M14: =IF(A14=Assumptions!$B$9,Assumptions!$B$69+Assumptions!$B$72,0)+IF(A14=$AE$4,Assumptions!$B$70+Assumptions!$B$71+Assumptions!$B$73,0) | N14: =E14*DevBudget!$B$16 | O14: =SUM(F14:N14) | P14: =P13+O14 | Q14: =MIN(O14,MAX(0,DevBudget!$B$19-R13)) | R14: =R13+Q14 | S14: =MIN(MAX(0,O14-Q14),MAX(0,Assumptions!$B$24-T14-U14)) | T14: =W13 | U14: =T14*Assumptions!$B$25/12 | V14: =MIN(T14+U14+S14,MAX(0,Z14+AA14)) | W14: =T14+S14+U14-V14 | X14: =IF(AND(A14>=$AE$2,A14<=Assumptions!$B$58),(MIN(Program!$D$5,MAX(0,(A14-$AE$2+1)*Assumptions!$B$39))*Assumptions!$B$29*(1+Assumptions!$B$31)*(1-Assumptions!$B$32)+Program!$D$9*Assumptions!$B$43*Assumptions!$B$44/12+Program!$D$5*Assumptions!$B$35*Assumptions!$B$34-Program!$D$5*Assumptions!$B$33/12-Assumptions!$B$36*Assumptions!$B$38/12),0) | Y14: =IF(AND(A14>=$AE$4,A14<=Assumptions!$B$59),(MIN(Program!$C$5,MAX(0,(A14-$AE$4+1)*Assumptions!$B$39))*Assumptions!$B$30*(1+Assumptions!$B$31)*(1-Assumptions!$B$32)+Program!$C$9*Assumptions!$B$43*Assumptions!$B$44/12+Program!$C$5*Assumptions!$B$35*Assumptions!$B$34-Program!$C$5*Assumptions!$B$33/12-Assumptions!$B$37*Assumptions!$B$38/12),0) | Z14: =SUMIF(Sellout!$A$6:$A$35,A14,Sellout!$D$6:$D$35)*(1-Assumptions!$B$49) | AA14: =IF(A14=Assumptions!$B$58,Ops!$B$23,0)+IF(A14=Assumptions!$B$59,Ops!$C$23,0) | AB14: =-O14+X14+Y14+Z14+AA14 | AC14: =AB14+S14-V14
A15: 10 | B15: =EDATE(Assumptions!$B$7,A15-1) | C15: =IF(A15<Assumptions!$B$9,"Pre-dev",IF(A15<$AE$2,"Construction",IF(A15<=Assumptions!$B$59,"Lease-up / exit","Tail"))) | D15: =IF(AND(A15>=Assumptions!$B$9,A15<$AE$2),(A15-Assumptions!$B$9+1)*($AE$2-A15),0) | E15: =IFERROR(D15/$AE$6,0) | F15: =IF(A15=1,DevBudget!$B$5,0) | G15: =E15*DevBudget!$B$6 | H15: =E15*DevBudget!$B$7 | I15: =E15*DevBudget!$B$8 | J15: =E15*(DevBudget!$B$9+DevBudget!$B$10) | K15: =E15*DevBudget!$B$12 | L15: =E15*DevBudget!$B$13 | M15: =IF(A15=Assumptions!$B$9,Assumptions!$B$69+Assumptions!$B$72,0)+IF(A15=$AE$4,Assumptions!$B$70+Assumptions!$B$71+Assumptions!$B$73,0) | N15: =E15*DevBudget!$B$16 | O15: =SUM(F15:N15) | P15: =P14+O15 | Q15: =MIN(O15,MAX(0,DevBudget!$B$19-R14)) | R15: =R14+Q15 | S15: =MIN(MAX(0,O15-Q15),MAX(0,Assumptions!$B$24-T15-U15)) | T15: =W14 | U15: =T15*Assumptions!$B$25/12 | V15: =MIN(T15+U15+S15,MAX(0,Z15+AA15)) | W15: =T15+S15+U15-V15 | X15: =IF(AND(A15>=$AE$2,A15<=Assumptions!$B$58),(MIN(Program!$D$5,MAX(0,(A15-$AE$2+1)*Assumptions!$B$39))*Assumptions!$B$29*(1+Assumptions!$B$31)*(1-Assumptions!$B$32)+Program!$D$9*Assumptions!$B$43*Assumptions!$B$44/12+Program!$D$5*Assumptions!$B$35*Assumptions!$B$34-Program!$D$5*Assumptions!$B$33/12-Assumptions!$B$36*Assumptions!$B$38/12),0) | Y15: =IF(AND(A15>=$AE$4,A15<=Assumptions!$B$59),(MIN(Program!$C$5,MAX(0,(A15-$AE$4+1)*Assumptions!$B$39))*Assumptions!$B$30*(1+Assumptions!$B$31)*(1-Assumptions!$B$32)+Program!$C$9*Assumptions!$B$43*Assumptions!$B$44/12+Program!$C$5*Assumptions!$B$35*Assumptions!$B$34-Program!$C$5*Assumptions!$B$33/12-Assumptions!$B$37*Assumptions!$B$38/12),0) | Z15: =SUMIF(Sellout!$A$6:$A$35,A15,Sellout!$D$6:$D$35)*(1-Assumptions!$B$49) | AA15: =IF(A15=Assumptions!$B$58,Ops!$B$23,0)+IF(A15=Assumptions!$B$59,Ops!$C$23,0) | AB15: =-O15+X15+Y15+Z15+AA15 | AC15: =AB15+S15-V15
A16: 11 | B16: =EDATE(Assumptions!$B$7,A16-1) | C16: =IF(A16<Assumptions!$B$9,"Pre-dev",IF(A16<$AE$2,"Construction",IF(A16<=Assumptions!$B$59,"Lease-up / exit","Tail"))) | D16: =IF(AND(A16>=Assumptions!$B$9,A16<$AE$2),(A16-Assumptions!$B$9+1)*($AE$2-A16),0) | E16: =IFERROR(D16/$AE$6,0) | F16: =IF(A16=1,DevBudget!$B$5,0) | G16: =E16*DevBudget!$B$6 | H16: =E16*DevBudget!$B$7 | I16: =E16*DevBudget!$B$8 | J16: =E16*(DevBudget!$B$9+DevBudget!$B$10) | K16: =E16*DevBudget!$B$12 | L16: =E16*DevBudget!$B$13 | M16: =IF(A16=Assumptions!$B$9,Assumptions!$B$69+Assumptions!$B$72,0)+IF(A16=$AE$4,Assumptions!$B$70+Assumptions!$B$71+Assumptions!$B$73,0) | N16: =E16*DevBudget!$B$16 | O16: =SUM(F16:N16) | P16: =P15+O16 | Q16: =MIN(O16,MAX(0,DevBudget!$B$19-R15)) | R16: =R15+Q16 | S16: =MIN(MAX(0,O16-Q16),MAX(0,Assumptions!$B$24-T16-U16)) | T16: =W15 | U16: =T16*Assumptions!$B$25/12 | V16: =MIN(T16+U16+S16,MAX(0,Z16+AA16)) | W16: =T16+S16+U16-V16 | X16: =IF(AND(A16>=$AE$2,A16<=Assumptions!$B$58),(MIN(Program!$D$5,MAX(0,(A16-$AE$2+1)*Assumptions!$B$39))*Assumptions!$B$29*(1+Assumptions!$B$31)*(1-Assumptions!$B$32)+Program!$D$9*Assumptions!$B$43*Assumptions!$B$44/12+Program!$D$5*Assumptions!$B$35*Assumptions!$B$34-Program!$D$5*Assumptions!$B$33/12-Assumptions!$B$36*Assumptions!$B$38/12),0) | Y16: =IF(AND(A16>=$AE$4,A16<=Assumptions!$B$59),(MIN(Program!$C$5,MAX(0,(A16-$AE$4+1)*Assumptions!$B$39))*Assumptions!$B$30*(1+Assumptions!$B$31)*(1-Assumptions!$B$32)+Program!$C$9*Assumptions!$B$43*Assumptions!$B$44/12+Program!$C$5*Assumptions!$B$35*Assumptions!$B$34-Program!$C$5*Assumptions!$B$33/12-Assumptions!$B$37*Assumptions!$B$38/12),0) | Z16: =SUMIF(Sellout!$A$6:$A$35,A16,Sellout!$D$6:$D$35)*(1-Assumptions!$B$49) | AA16: =IF(A16=Assumptions!$B$58,Ops!$B$23,0)+IF(A16=Assumptions!$B$59,Ops!$C$23,0) | AB16: =-O16+X16+Y16+Z16+AA16 | AC16: =AB16+S16-V16
A17: 12 | B17: =EDATE(Assumptions!$B$7,A17-1) | C17: =IF(A17<Assumptions!$B$9,"Pre-dev",IF(A17<$AE$2,"Construction",IF(A17<=Assumptions!$B$59,"Lease-up / exit","Tail"))) | D17: =IF(AND(A17>=Assumptions!$B$9,A17<$AE$2),(A17-Assumptions!$B$9+1)*($AE$2-A17),0) | E17: =IFERROR(D17/$AE$6,0) | F17: =IF(A17=1,DevBudget!$B$5,0) | G17: =E17*DevBudget!$B$6 | H17: =E17*DevBudget!$B$7 | I17: =E17*DevBudget!$B$8 | J17: =E17*(DevBudget!$B$9+DevBudget!$B$10) | K17: =E17*DevBudget!$B$12 | L17: =E17*DevBudget!$B$13 | M17: =IF(A17=Assumptions!$B$9,Assumptions!$B$69+Assumptions!$B$72,0)+IF(A17=$AE$4,Assumptions!$B$70+Assumptions!$B$71+Assumptions!$B$73,0) | N17: =E17*DevBudget!$B$16 | O17: =SUM(F17:N17) | P17: =P16+O17 | Q17: =MIN(O17,MAX(0,DevBudget!$B$19-R16)) | R17: =R16+Q17 | S17: =MIN(MAX(0,O17-Q17),MAX(0,Assumptions!$B$24-T17-U17)) | T17: =W16 | U17: =T17*Assumptions!$B$25/12 | V17: =MIN(T17+U17+S17,MAX(0,Z17+AA17)) | W17: =T17+S17+U17-V17 | X17: =IF(AND(A17>=$AE$2,A17<=Assumptions!$B$58),(MIN(Program!$D$5,MAX(0,(A17-$AE$2+1)*Assumptions!$B$39))*Assumptions!$B$29*(1+Assumptions!$B$31)*(1-Assumptions!$B$32)+Program!$D$9*Assumptions!$B$43*Assumptions!$B$44/12+Program!$D$5*Assumptions!$B$35*Assumptions!$B$34-Program!$D$5*Assumptions!$B$33/12-Assumptions!$B$36*Assumptions!$B$38/12),0) | Y17: =IF(AND(A17>=$AE$4,A17<=Assumptions!$B$59),(MIN(Program!$C$5,MAX(0,(A17-$AE$4+1)*Assumptions!$B$39))*Assumptions!$B$30*(1+Assumptions!$B$31)*(1-Assumptions!$B$32)+Program!$C$9*Assumptions!$B$43*Assumptions!$B$44/12+Program!$C$5*Assumptions!$B$35*Assumptions!$B$34-Program!$C$5*Assumptions!$B$33/12-Assumptions!$B$37*Assumptions!$B$38/12),0) | Z17: =SUMIF(Sellout!$A$6:$A$35,A17,Sellout!$D$6:$D$35)*(1-Assumptions!$B$49) | AA17: =IF(A17=Assumptions!$B$58,Ops!$B$23,0)+IF(A17=Assumptions!$B$59,Ops!$C$23,0) | AB17: =-O17+X17+Y17+Z17+AA17 | AC17: =AB17+S17-V17
A18: 13 | B18: =EDATE(Assumptions!$B$7,A18-1) | C18: =IF(A18<Assumptions!$B$9,"Pre-dev",IF(A18<$AE$2,"Construction",IF(A18<=Assumptions!$B$59,"Lease-up / exit","Tail"))) | D18: =IF(AND(A18>=Assumptions!$B$9,A18<$AE$2),(A18-Assumptions!$B$9+1)*($AE$2-A18),0) | E18: =IFERROR(D18/$AE$6,0) | F18: =IF(A18=1,DevBudget!$B$5,0) | G18: =E18*DevBudget!$B$6 | H18: =E18*DevBudget!$B$7 | I18: =E18*DevBudget!$B$8 | J18: =E18*(DevBudget!$B$9+DevBudget!$B$10) | K18: =E18*DevBudget!$B$12 | L18: =E18*DevBudget!$B$13 | M18: =IF(A18=Assumptions!$B$9,Assumptions!$B$69+Assumptions!$B$72,0)+IF(A18=$AE$4,Assumptions!$B$70+Assumptions!$B$71+Assumptions!$B$73,0) | N18: =E18*DevBudget!$B$16 | O18: =SUM(F18:N18) | P18: =P17+O18 | Q18: =MIN(O18,MAX(0,DevBudget!$B$19-R17)) | R18: =R17+Q18 | S18: =MIN(MAX(0,O18-Q18),MAX(0,Assumptions!$B$24-T18-U18)) | T18: =W17 | U18: =T18*Assumptions!$B$25/12 | V18: =MIN(T18+U18+S18,MAX(0,Z18+AA18)) | W18: =T18+S18+U18-V18 | X18: =IF(AND(A18>=$AE$2,A18<=Assumptions!$B$58),(MIN(Program!$D$5,MAX(0,(A18-$AE$2+1)*Assumptions!$B$39))*Assumptions!$B$29*(1+Assumptions!$B$31)*(1-Assumptions!$B$32)+Program!$D$9*Assumptions!$B$43*Assumptions!$B$44/12+Program!$D$5*Assumptions!$B$35*Assumptions!$B$34-Program!$D$5*Assumptions!$B$33/12-Assumptions!$B$36*Assumptions!$B$38/12),0) | Y18: =IF(AND(A18>=$AE$4,A18<=Assumptions!$B$59),(MIN(Program!$C$5,MAX(0,(A18-$AE$4+1)*Assumptions!$B$39))*Assumptions!$B$30*(1+Assumptions!$B$31)*(1-Assumptions!$B$32)+Program!$C$9*Assumptions!$B$43*Assumptions!$B$44/12+Program!$C$5*Assumptions!$B$35*Assumptions!$B$34-Program!$C$5*Assumptions!$B$33/12-Assumptions!$B$37*Assumptions!$B$38/12),0) | Z18: =SUMIF(Sellout!$A$6:$A$35,A18,Sellout!$D$6:$D$35)*(1-Assumptions!$B$49) | AA18: =IF(A18=Assumptions!$B$58,Ops!$B$23,0)+IF(A18=Assumptions!$B$59,Ops!$C$23,0) | AB18: =-O18+X18+Y18+Z18+AA18 | AC18: =AB18+S18-V18
... A165: 160 | B165: =EDATE(Assumptions!$B$7,A165-1) | C165: =IF(A165<Assumptions!$B$9,"Pre-dev",IF(A165<$AE$2,"Construction",IF(A165<=Assumptions!$B$59,"Lease-up / exit","Tail"))) | D165: =IF(AND(A165>=Assumptions!$B$9,A165<$AE$2),(A165-Assumptions!$B$9+1)*($AE$2-A165),0) | E165: =IFERROR(D165/$AE$6,0) | F165: =IF(A165=1,DevBudget!$B$5,0) | G165: =E165*DevBudget!$B$6 | H165: =E165*DevBudget!$B$7 | I165: =E165*DevBudget!$B$8 | J165: =E165*(DevBudget!$B$9+DevBudget!$B$10) | K165: =E165*DevBudget!$B$12 | L165: =E165*DevBudget!$B$13 | M165: =IF(A165=Assumptions!$B$9,Assumptions!$B$69+Assumptions!$B$72,0)+IF(A165=$AE$4,Assumptions!$B$70+Assumptions!$B$71+Assumptions!$B$73,0) | N165: =E165*DevBudget!$B$16 | O165: =SUM(F165:N165) | P165: =P164+O165 | Q165: =MIN(O165,MAX(0,DevBudget!$B$19-R164)) | R165: =R164+Q165 | S165: =MIN(MAX(0,O165-Q165),MAX(0,Assumptions!$B$24-T165-U165)) | T165: =W164 | U165: =T165*Assumptions!$B$25/12 | V165: =MIN(T165+U165+S165,MAX(0,Z165+AA165)) | W165: =T165+S165+U165-V165 | X165: =IF(AND(A165>=$AE$2,A165<=Assumptions!$B$58),(MIN(Program!$D$5,MAX(0,(A165-$AE$2+1)*Assumptions!$B$39))*Assumptions!$B$29*(1+Assumptions!$B$31)*(1-Assumptions!$B$32)+Program!$D$9*Assumptions!$B$43*Assumptions!$B$44/12+Program!$D$5*Assumptions!$B$35*Assumptions!$B$34-Program!$D$5*Assumptions!$B$33/12-Assumptions!$B$36*Assumptions!$B$38/12),0) | Y165: =IF(AND(A165>=$AE$4,A165<=Assumptions!$B$59),(MIN(Program!$C$5,MAX(0,(A165-$AE$4+1)*Assumptions!$B$39))*Assumptions!$B$30*(1+Assumptions!$B$31)*(1-Assumptions!$B$32)+Program!$C$9*Assumptions!$B$43*Assumptions!$B$44/12+Program!$C$5*Assumptions!$B$35*Assumptions!$B$34-Program!$C$5*Assumptions!$B$33/12-Assumptions!$B$37*Assumptions!$B$38/12),0) | Z165: =SUMIF(Sellout!$A$6:$A$35,A165,Sellout!$D$6:$D$35)*(1-Assumptions!$B$49) | AA165: =IF(A165=Assumptions!$B$58,Ops!$B$23,0)+IF(A165=Assumptions!$B$59,Ops!$C$23,0) | AB165: =-O165+X165+Y165+Z165+AA165 | AC165: =AB165+S165-V165
A166: TOTAL | F166: =SUM(F6:F165) | G166: =SUM(G6:G165) | H166: =SUM(H6:H165) | I166: =SUM(I6:I165) | J166: =SUM(J6:J165) | K166: =SUM(K6:K165) | L166: =SUM(L6:L165) | M166: =SUM(M6:M165) | ... S166: =SUM(S6:S165) | U166: =SUM(U6:U165) | V166: =SUM(V6:V165) | X166: =SUM(X6:X165) | Y166: =SUM(Y6:Y165) | Z166: =SUM(Z6:Z165) | AA166: =SUM(AA6:AA165) | AB166: =SUM(AB6:AB165) | AC166: =SUM(AC6:AC165)

Sheet Waterfall
A1: JV WATERFALL — investor capital vs sponsor promote
A2: Two capital accounts: one accreting at the preferred return, one at the tier-2 hurdle. Tier-1 distributions also reduce the tier-2 account, so the hurdles are cumulative, not additive.
A3: ASSUMPTION IN FULL: the Baupost JV terms are not public. Every rate on this sheet is a placeholder.
A5: Month # | B5: Date | C5: Equity CF | D5: Contribution | E5: Distributable | F5: Pref acct BOP | G5: Pref accrual | H5: Pref acct + contrib | I5: Tier 1 dist | J5: Pref acct EOP | K5: Hurdle2 acct BOP | L5: Hurdle2 accrual | M5: Hurdle2 + contrib | N5: Tier 2 total | O5: Tier 2 to investors | P5: Promote tier 1 | Q5: Hurdle2 acct EOP | R5: Residual | S5: Residual to investors | T5: Promote tier 2 | U5: TOTAL to investors | V5: TOTAL promote | W5: LP cash flow | X5: Sponsor cash flow
A6: =CashFlow!A6 | B6: =CashFlow!B6 | C6: =CashFlow!AC6 | D6: =MAX(0,-C6) | E6: =MAX(0,C6) | F6: =0 | G6: =F6*Assumptions!$B$63/12 | H6: =F6+G6+D6 | I6: =MIN(E6,H6) | J6: =H6-I6 | K6: =0 | L6: =K6*Assumptions!$B$66/12 | M6: =K6+L6+D6 | N6: =MIN(MAX(0,E6-I6),MAX(0,M6-I6)/(1-Assumptions!$B$64)) | O6: =N6*(1-Assumptions!$B$64) | P6: =N6*Assumptions!$B$64 | Q6: =MAX(0,M6-I6-O6) | R6: =MAX(0,E6-I6-N6) | S6: =R6*(1-Assumptions!$B$65) | T6: =R6*Assumptions!$B$65 | U6: =I6+O6+S6 | V6: =P6+T6 | W6: =(1-Assumptions!$B$62)*(U6-D6) | X6: =Assumptions!$B$62*(U6-D6)+V6
A7: =CashFlow!A7 | B7: =CashFlow!B7 | C7: =CashFlow!AC7 | D7: =MAX(0,-C7) | E7: =MAX(0,C7) | F7: =J6 | G7: =F7*Assumptions!$B$63/12 | H7: =F7+G7+D7 | I7: =MIN(E7,H7) | J7: =H7-I7 | K7: =Q6 | L7: =K7*Assumptions!$B$66/12 | M7: =K7+L7+D7 | N7: =MIN(MAX(0,E7-I7),MAX(0,M7-I7)/(1-Assumptions!$B$64)) | O7: =N7*(1-Assumptions!$B$64) | P7: =N7*Assumptions!$B$64 | Q7: =MAX(0,M7-I7-O7) | R7: =MAX(0,E7-I7-N7) | S7: =R7*(1-Assumptions!$B$65) | T7: =R7*Assumptions!$B$65 | U7: =I7+O7+S7 | V7: =P7+T7 | W7: =(1-Assumptions!$B$62)*(U7-D7) | X7: =Assumptions!$B$62*(U7-D7)+V7
A8: =CashFlow!A8 | B8: =CashFlow!B8 | C8: =CashFlow!AC8 | D8: =MAX(0,-C8) | E8: =MAX(0,C8) | F8: =J7 | G8: =F8*Assumptions!$B$63/12 | H8: =F8+G8+D8 | I8: =MIN(E8,H8) | J8: =H8-I8 | K8: =Q7 | L8: =K8*Assumptions!$B$66/12 | M8: =K8+L8+D8 | N8: =MIN(MAX(0,E8-I8),MAX(0,M8-I8)/(1-Assumptions!$B$64)) | O8: =N8*(1-Assumptions!$B$64) | P8: =N8*Assumptions!$B$64 | Q8: =MAX(0,M8-I8-O8) | R8: =MAX(0,E8-I8-N8) | S8: =R8*(1-Assumptions!$B$65) | T8: =R8*Assumptions!$B$65 | U8: =I8+O8+S8 | V8: =P8+T8 | W8: =(1-Assumptions!$B$62)*(U8-D8) | X8: =Assumptions!$B$62*(U8-D8)+V8
A9: =CashFlow!A9 | B9: =CashFlow!B9 | C9: =CashFlow!AC9 | D9: =MAX(0,-C9) | E9: =MAX(0,C9) | F9: =J8 | G9: =F9*Assumptions!$B$63/12 | H9: =F9+G9+D9 | I9: =MIN(E9,H9) | J9: =H9-I9 | K9: =Q8 | L9: =K9*Assumptions!$B$66/12 | M9: =K9+L9+D9 | N9: =MIN(MAX(0,E9-I9),MAX(0,M9-I9)/(1-Assumptions!$B$64)) | O9: =N9*(1-Assumptions!$B$64) | P9: =N9*Assumptions!$B$64 | Q9: =MAX(0,M9-I9-O9) | R9: =MAX(0,E9-I9-N9) | S9: =R9*(1-Assumptions!$B$65) | T9: =R9*Assumptions!$B$65 | U9: =I9+O9+S9 | V9: =P9+T9 | W9: =(1-Assumptions!$B$62)*(U9-D9) | X9: =Assumptions!$B$62*(U9-D9)+V9
A10: =CashFlow!A10 | B10: =CashFlow!B10 | C10: =CashFlow!AC10 | D10: =MAX(0,-C10) | E10: =MAX(0,C10) | F10: =J9 | G10: =F10*Assumptions!$B$63/12 | H10: =F10+G10+D10 | I10: =MIN(E10,H10) | J10: =H10-I10 | K10: =Q9 | L10: =K10*Assumptions!$B$66/12 | M10: =K10+L10+D10 | N10: =MIN(MAX(0,E10-I10),MAX(0,M10-I10)/(1-Assumptions!$B$64)) | O10: =N10*(1-Assumptions!$B$64) | P10: =N10*Assumptions!$B$64 | Q10: =MAX(0,M10-I10-O10) | R10: =MAX(0,E10-I10-N10) | S10: =R10*(1-Assumptions!$B$65) | T10: =R10*Assumptions!$B$65 | U10: =I10+O10+S10 | V10: =P10+T10 | W10: =(1-Assumptions!$B$62)*(U10-D10) | X10: =Assumptions!$B$62*(U10-D10)+V10
A11: =CashFlow!A11 | B11: =CashFlow!B11 | C11: =CashFlow!AC11 | D11: =MAX(0,-C11) | E11: =MAX(0,C11) | F11: =J10 | G11: =F11*Assumptions!$B$63/12 | H11: =F11+G11+D11 | I11: =MIN(E11,H11) | J11: =H11-I11 | K11: =Q10 | L11: =K11*Assumptions!$B$66/12 | M11: =K11+L11+D11 | N11: =MIN(MAX(0,E11-I11),MAX(0,M11-I11)/(1-Assumptions!$B$64)) | O11: =N11*(1-Assumptions!$B$64) | P11: =N11*Assumptions!$B$64 | Q11: =MAX(0,M11-I11-O11) | R11: =MAX(0,E11-I11-N11) | S11: =R11*(1-Assumptions!$B$65) | T11: =R11*Assumptions!$B$65 | U11: =I11+O11+S11 | V11: =P11+T11 | W11: =(1-Assumptions!$B$62)*(U11-D11) | X11: =Assumptions!$B$62*(U11-D11)+V11
A12: =CashFlow!A12 | B12: =CashFlow!B12 | C12: =CashFlow!AC12 | D12: =MAX(0,-C12) | E12: =MAX(0,C12) | F12: =J11 | G12: =F12*Assumptions!$B$63/12 | H12: =F12+G12+D12 | I12: =MIN(E12,H12) | J12: =H12-I12 | K12: =Q11 | L12: =K12*Assumptions!$B$66/12 | M12: =K12+L12+D12 | N12: =MIN(MAX(0,E12-I12),MAX(0,M12-I12)/(1-Assumptions!$B$64)) | O12: =N12*(1-Assumptions!$B$64) | P12: =N12*Assumptions!$B$64 | Q12: =MAX(0,M12-I12-O12) | R12: =MAX(0,E12-I12-N12) | S12: =R12*(1-Assumptions!$B$65) | T12: =R12*Assumptions!$B$65 | U12: =I12+O12+S12 | V12: =P12+T12 | W12: =(1-Assumptions!$B$62)*(U12-D12) | X12: =Assumptions!$B$62*(U12-D12)+V12
A13: =CashFlow!A13 | B13: =CashFlow!B13 | C13: =CashFlow!AC13 | D13: =MAX(0,-C13) | E13: =MAX(0,C13) | F13: =J12 | G13: =F13*Assumptions!$B$63/12 | H13: =F13+G13+D13 | I13: =MIN(E13,H13) | J13: =H13-I13 | K13: =Q12 | L13: =K13*Assumptions!$B$66/12 | M13: =K13+L13+D13 | N13: =MIN(MAX(0,E13-I13),MAX(0,M13-I13)/(1-Assumptions!$B$64)) | O13: =N13*(1-Assumptions!$B$64) | P13: =N13*Assumptions!$B$64 | Q13: =MAX(0,M13-I13-O13) | R13: =MAX(0,E13-I13-N13) | S13: =R13*(1-Assumptions!$B$65) | T13: =R13*Assumptions!$B$65 | U13: =I13+O13+S13 | V13: =P13+T13 | W13: =(1-Assumptions!$B$62)*(U13-D13) | X13: =Assumptions!$B$62*(U13-D13)+V13
A14: =CashFlow!A14 | B14: =CashFlow!B14 | C14: =CashFlow!AC14 | D14: =MAX(0,-C14) | E14: =MAX(0,C14) | F14: =J13 | G14: =F14*Assumptions!$B$63/12 | H14: =F14+G14+D14 | I14: =MIN(E14,H14) | J14: =H14-I14 | K14: =Q13 | L14: =K14*Assumptions!$B$66/12 | M14: =K14+L14+D14 | N14: =MIN(MAX(0,E14-I14),MAX(0,M14-I14)/(1-Assumptions!$B$64)) | O14: =N14*(1-Assumptions!$B$64) | P14: =N14*Assumptions!$B$64 | Q14: =MAX(0,M14-I14-O14) | R14: =MAX(0,E14-I14-N14) | S14: =R14*(1-Assumptions!$B$65) | T14: =R14*Assumptions!$B$65 | U14: =I14+O14+S14 | V14: =P14+T14 | W14: =(1-Assumptions!$B$62)*(U14-D14) | X14: =Assumptions!$B$62*(U14-D14)+V14
A15: =CashFlow!A15 | B15: =CashFlow!B15 | C15: =CashFlow!AC15 | D15: =MAX(0,-C15) | E15: =MAX(0,C15) | F15: =J14 | G15: =F15*Assumptions!$B$63/12 | H15: =F15+G15+D15 | I15: =MIN(E15,H15) | J15: =H15-I15 | K15: =Q14 | L15: =K15*Assumptions!$B$66/12 | M15: =K15+L15+D15 | N15: =MIN(MAX(0,E15-I15),MAX(0,M15-I15)/(1-Assumptions!$B$64)) | O15: =N15*(1-Assumptions!$B$64) | P15: =N15*Assumptions!$B$64 | Q15: =MAX(0,M15-I15-O15) | R15: =MAX(0,E15-I15-N15) | S15: =R15*(1-Assumptions!$B$65) | T15: =R15*Assumptions!$B$65 | U15: =I15+O15+S15 | V15: =P15+T15 | W15: =(1-Assumptions!$B$62)*(U15-D15) | X15: =Assumptions!$B$62*(U15-D15)+V15
A16: =CashFlow!A16 | B16: =CashFlow!B16 | C16: =CashFlow!AC16 | D16: =MAX(0,-C16) | E16: =MAX(0,C16) | F16: =J15 | G16: =F16*Assumptions!$B$63/12 | H16: =F16+G16+D16 | I16: =MIN(E16,H16) | J16: =H16-I16 | K16: =Q15 | L16: =K16*Assumptions!$B$66/12 | M16: =K16+L16+D16 | N16: =MIN(MAX(0,E16-I16),MAX(0,M16-I16)/(1-Assumptions!$B$64)) | O16: =N16*(1-Assumptions!$B$64) | P16: =N16*Assumptions!$B$64 | Q16: =MAX(0,M16-I16-O16) | R16: =MAX(0,E16-I16-N16) | S16: =R16*(1-Assumptions!$B$65) | T16: =R16*Assumptions!$B$65 | U16: =I16+O16+S16 | V16: =P16+T16 | W16: =(1-Assumptions!$B$62)*(U16-D16) | X16: =Assumptions!$B$62*(U16-D16)+V16
A17: =CashFlow!A17 | B17: =CashFlow!B17 | C17: =CashFlow!AC17 | D17: =MAX(0,-C17) | E17: =MAX(0,C17) | F17: =J16 | G17: =F17*Assumptions!$B$63/12 | H17: =F17+G17+D17 | I17: =MIN(E17,H17) | J17: =H17-I17 | K17: =Q16 | L17: =K17*Assumptions!$B$66/12 | M17: =K17+L17+D17 | N17: =MIN(MAX(0,E17-I17),MAX(0,M17-I17)/(1-Assumptions!$B$64)) | O17: =N17*(1-Assumptions!$B$64) | P17: =N17*Assumptions!$B$64 | Q17: =MAX(0,M17-I17-O17) | R17: =MAX(0,E17-I17-N17) | S17: =R17*(1-Assumptions!$B$65) | T17: =R17*Assumptions!$B$65 | U17: =I17+O17+S17 | V17: =P17+T17 | W17: =(1-Assumptions!$B$62)*(U17-D17) | X17: =Assumptions!$B$62*(U17-D17)+V17
A18: =CashFlow!A18 | B18: =CashFlow!B18 | C18: =CashFlow!AC18 | D18: =MAX(0,-C18) | E18: =MAX(0,C18) | F18: =J17 | G18: =F18*Assumptions!$B$63/12 | H18: =F18+G18+D18 | I18: =MIN(E18,H18) | J18: =H18-I18 | K18: =Q17 | L18: =K18*Assumptions!$B$66/12 | M18: =K18+L18+D18 | N18: =MIN(MAX(0,E18-I18),MAX(0,M18-I18)/(1-Assumptions!$B$64)) | O18: =N18*(1-Assumptions!$B$64) | P18: =N18*Assumptions!$B$64 | Q18: =MAX(0,M18-I18-O18) | R18: =MAX(0,E18-I18-N18) | S18: =R18*(1-Assumptions!$B$65) | T18: =R18*Assumptions!$B$65 | U18: =I18+O18+S18 | V18: =P18+T18 | W18: =(1-Assumptions!$B$62)*(U18-D18) | X18: =Assumptions!$B$62*(U18-D18)+V18
... A165: =CashFlow!A165 | B165: =CashFlow!B165 | C165: =CashFlow!AC165 | D165: =MAX(0,-C165) | E165: =MAX(0,C165) | F165: =J164 | G165: =F165*Assumptions!$B$63/12 | H165: =F165+G165+D165 | I165: =MIN(E165,H165) | J165: =H165-I165 | K165: =Q164 | L165: =K165*Assumptions!$B$66/12 | M165: =K165+L165+D165 | N165: =MIN(MAX(0,E165-I165),MAX(0,M165-I165)/(1-Assumptions!$B$64)) | O165: =N165*(1-Assumptions!$B$64) | P165: =N165*Assumptions!$B$64 | Q165: =MAX(0,M165-I165-O165) | R165: =MAX(0,E165-I165-N165) | S165: =R165*(1-Assumptions!$B$65) | T165: =R165*Assumptions!$B$65 | U165: =I165+O165+S165 | V165: =P165+T165 | W165: =(1-Assumptions!$B$62)*(U165-D165) | X165: =Assumptions!$B$62*(U165-D165)+V165
A166: TOTAL | C166: =SUM(C6:C165) | D166: =SUM(D6:D165) | E166: =SUM(E6:E165) | G166: =SUM(G6:G165) | I166: =SUM(I6:I165) | L166: =SUM(L6:L165) | N166: =SUM(N6:N165) | O166: =SUM(O6:O165) | P166: =SUM(P6:P165) | R166: =SUM(R6:R165) | S166: =SUM(S6:S165) | T166: =SUM(T6:T165) | U166: =SUM(U6:U165) | V166: =SUM(V6:V165) | W166: =SUM(W6:W165) | X166: =SUM(X6:X165)

Sheet Returns
A1: RETURNS
A2: Every figure here rests on the Assumptions sheet. None of it is a claim about what Penzance actually earned.
A4: Metric | B4: Value | C4: Unit | D4: Note
A6: SOURCES & USES
A7: Total development cost | B7: =CashFlow!O166 | C7: $ | D7: Excludes capitalised interest
A8: Capitalised interest | B8: =CashFlow!U166 | C8: $ | D8: Accrued into the loan balance, never a cash line
A9: Total project cost | B9: =B7+B8 | C9: $
A10: Peak equity | B10: =MAX(CashFlow!R6:R165) | C10: $
A11: Peak debt | B11: =MAX(CashFlow!W6:W165) | C11: $
A12: Loan commitment (reported) | B12: =Assumptions!$B$24 | C12: $ | D12: Press-reported; unverified to the recorded instrument
A13: Peak debt vs commitment | B13: =IFERROR(B11/B12,0) | C13: % | D13: THE KEY CALIBRATION. Near 100% means the cost assumptions are consistent with the one hard capital-stack datapoint we have. Far below means costs are understated; above 100% means overstated.
A15: PROCEEDS
A16: Pierce net sellout | B16: =CashFlow!Z166 | C16: $ | D16: 104 units
A17: Aubrey + Evo net sale proceeds | B17: =CashFlow!AA166 | C17: $ | D17: Struck at stabilised NOI / cap — Cortland terms undisclosed
A18: Operating NOI collected | B18: =CashFlow!X166+CashFlow!Y166 | C18: $ | D18: NEGATIVE is expected and correct here: both towers were sold roughly a year after delivery, so they carried full operating expense against partial occupancy for their whole hold. See the lease-up note below.
A19: Total proceeds | B19: =B16+B17+B18 | C19: $
A21: PROJECT RETURNS
A22: Unlevered profit | B22: =CashFlow!AB166 | C22: $
A23: Unlevered IRR | B23: =IFERROR((1+IRR(CashFlow!AB6:AB165,0.01))^12-1,0) | C23: % | D23: Monthly IRR annualised
A24: Unlevered multiple | B24: =IFERROR(SUMIF(CashFlow!AB6:AB165,">0")/-SUMIF(CashFlow!AB6:AB165,"<0"),0) | C24: x
A25: Levered profit (equity) | B25: =CashFlow!AC166 | C25: $
A26: Levered IRR | B26: =IFERROR((1+IRR(CashFlow!AC6:AC165,0.01))^12-1,0) | C26: %
A27: Equity multiple | B27: =IFERROR(SUMIF(CashFlow!AC6:AC165,">0")/-SUMIF(CashFlow!AC6:AC165,"<0"),0) | C27: x
A29: JV SPLIT (assumed terms — Baupost JV is not public)
A30: Total to investors (pro rata) | B30: =Waterfall!U166 | C30: $
A31: Total sponsor promote | B31: =Waterfall!V166 | C31: $ | D31: Zero if the deal never clears the preferred return
A32: LP net profit | B32: =Waterfall!W166 | C32: $
A33: Sponsor net profit | B33: =Waterfall!X166 | C33: $
A34: LP IRR | B34: =IFERROR((1+IRR(Waterfall!W6:W165,0.01))^12-1,0) | C34: %
A35: Sponsor IRR | B35: =IFERROR((1+IRR(Waterfall!X6:X165,0.01))^12-1,0) | C35: %
A37: CALIBRATION CHECKS — read these before quoting anything above
A38: Total cost per unit | B38: =IFERROR(B9/Program!$B$13,0) | C38: $/unit | D38: All-in incl. capitalised interest, the fire station, the park and the street
A39: Total cost per sf of GFA | B39: =IFERROR(B9/Program!$B$14,0) | C39: $/sf
A40: Aubrey exit $/unit (FACT) | B40: =Ops!$B$19 | C40: $/unit | D40: Derived from the Evo sale/assessment ratio — leasehold, no recorded price
A41: Evo exit $/unit (FACT) | B41: =Ops!$C$19 | C41: $/unit | D41: $334,642,240 recorded 2022-07-12 / 453 units
A42: Aubrey + Evo blended $/unit | B42: =IFERROR((Ops!$B$18+Ops!$C$18)/(Program!$D$5+Program!$C$5),0) | C42: $/unit | D42: Lands on ~$764k against the ~$758k Cortland blended figure — independent corroboration of the derivation
A43: Implied LOADED cap — Aubrey | B43: =Ops!$B$20 | C43: % | D43: vs Arlington's 5.15% guideline for this class
A44: Implied LOADED cap — Evo | B44: =Ops!$C$20 | C44: % | D44: Both prices are FACT; both caps land ~4.4%
A45: Implied BASE cap — Aubrey | B45: =Ops!$B$21 | C45: % | D45: Loaded less the 1.013% effective tax rate
A46: Implied BASE cap — Evo | B46: =Ops!$C$21 | C46: % | D46: The number a broker would quote for this trade
...
